Workbook

Sheet Config
A1: Parameter | B1: Value | C1: Notes
A2: Reservoir_Name | B2: Mae Na Rua
A3: AsOf_Time | B3: 07:00 | C3: Reference time for 'Date' row
A4: Storage_Max_m3 | B4: 1625463.8 | C4: S_max (m³) at full supply level
A5: API_k | B5: 0.95 | C5: Antecedent Precipitation Index decay (0.90–0.98) | D5: ตัวแทนความชื้นลุ่มน้ำ
A6: Days_in_Year | B6: 365 | C6: Use 366 if you prefer leap-year handling

Sheet Daily_Input
A1: Date (YYYY-MM-DD) | B1: AsOf_Time (HH:MM) | C1: Reservoir_Name | D1: Water_Level_MSL (m) | E1: Storage_S (m³) | F1: Q_in (m³/day) [Observed] | G1: Outflow_O (m³/day) | H1: Spill (m³/day) | I1: Rain_24h (mm) [Observed] | J1: Rain_Direct_to_Reservoir (m³/day) | K1: Evaporation_E (m³/day) | L1: Infiltration (m³/day) | M1: Notes / QC Flags | N1: Rain_Forecast_d1 (mm) [Issued at t] | O1: Rain_Forecast_d2 (mm) [Issued at t] | P1: Rain_Forecast_d3 (mm) [Issued at t]
A2: 45839 | B2: =Config!$B$3 -> 07:00 | C2: =Config!$B$2 -> Mae Na Rua | D2: 489.518 | E2: 1616447.3 | F2: 16137.621 | G2: 15019.2 | H2: 0 | I2: 0 | J2: 0 | K2: 813.96373 | L2: 304.45736 | N2: 13.673 | O2: 6.699 | P2: 4.328
A3: 45840 | B3: =Config!$B$3 -> 07:00 | C3: =Config!$B$2 -> Mae Na Rua | D3: 489.524 | E3: 1619451.3 | F3: 18000.43 | G3: 15019.2 | H3: 0 | I3: 3.8 | J3: 1141.7811 | K3: 814.37686 | L3: 304.61758 | N3: 6.699 | O3: 4.328 | P3: 10.32
A4: 45841 | B4: =Config!$B$3 -> 07:00 | C4: =Config!$B$2 -> Mae Na Rua | D4: 489.524 | E4: 1619451.3 | F4: 16551.136 | G4: 15019.2 | H4: 412.94112 | I4: 0 | J4: 0 | K4: 814.37686 | L4: 304.61758 | N4: 4.328 | O4: 10.32 | P4: 4.29
A5: 45842 | B5: =Config!$B$3 -> 07:00 | C5: =Config!$B$2 -> Mae Na Rua | D5: 489.557 | E5: 1628472.3 | F5: 21950.322 | G5: 15019.2 | H5: 5877.4746 | I5: 30.2 | J5: 9088.068 | K5: 815.62547 | L5: 305.10157 | N5: 10.32 | O5: 4.29 | P5: 1.138
A6: 45843 | B6: =Config!$B$3 -> 07:00 | C6: =Config!$B$2 -> Mae Na Rua | D6: 489.557 | E6: 1628472.3 | F6: 22689.828 | G6: 15019.2 | H6: 6670.2723 | I6: 0.4 | J6: 120.37176 | K6: 815.62547 | L6: 305.10157 | N6: 4.29 | O6: 1.138 | P6: 13.004
A7: 45844 | B7: =Config!$B$3 -> 07:00 | C7: =Config!$B$2 -> Mae Na Rua | D7: 489.577 | E7: 1634494 | F7: 41715.189 | G7: 15019.2 | H7: 24733.704 | I7: 17.2 | J7: 5181.3185 | K7: 816.4658 | L7: 305.42715 | N7: 1.138 | O7: 13.004 | P7: 9.394
A8: 45845 | B8: =Config!$B$3 -> 07:00 | C8: =Config!$B$2 -> Mae Na Rua | D8: 489.577 | E8: 1634494 | F8: 41682.058 | G8: 15019.2 | H8: 25540.965 | I8: 0 | J8: 0 | K8: 816.4658 | L8: 305.42715 | N8: 13.004 | O8: 9.394 | P8: 1.67
A9: 45846 | B9: =Config!$B$3 -> 07:00 | C9: =Config!$B$2 -> Mae Na Rua | D9: 489.577 | E9: 1634494 | F9: 38705.212 | G9: 15019.2 | H9: 22564.119 | I9: 0 | J9: 0 | K9: 816.4658 | L9: 305.42715 | N9: 9.394 | O9: 1.67 | P9: 10.659
A10: 45847 | B10: =Config!$B$3 -> 07:00 | C10: =Config!$B$2 -> Mae Na Rua | D10: 489.57 | E10: 1634494 | F10: 33915.235 | G10: 15019.2 | H10: 17774.142 | I10: 0 | J10: 0 | K10: 816.4658 | L10: 305.42715 | N10: 1.67 | O10: 10.659 | P10: 20.48
A11: 45848 | B11: =Config!$B$3 -> 07:00 | C11: =Config!$B$2 -> Mae Na Rua | D11: 489.564 | E11: 1631482.4 | F11: 16680.986 | G11: 15019.2 | H11: 6141.422 | I11: 8.6 | J11: 2589.3238 | K11: 816.04492 | L11: 305.26409 | N11: 10.659 | O11: 20.48 | P11: 22.463
A12: 45849 | B12: =Config!$B$3 -> 07:00 | C12: =Config!$B$2 -> Mae Na Rua | D12: 489.544 | E12: 1625463.8 | F12: 9699.6258 | G12: 15019.2 | H12: 0 | I12: 1.4 | J12: 421.08536 | K12: 815.20768 | L12: 304.93967 | N12: 20.48 | O12: 22.463 | P12: 18.722
A13: 45850 | B13: =Config!$B$3 -> 07:00 | C13: =Config!$B$2 -> Mae Na Rua | D13: 489.531 | E13: 1622456.8 | F13: 20534.223 | G13: 15019.2 | H13: 8965.6721 | I13: 5.2 | J13: 1563.2329 | K13: 814.79152 | L13: 304.77835 | N13: 22.463 | O13: 18.722 | P13: 18.886
... A128: 45965 | B128: =Config!$B$3 -> 07:00 | C128: =Config!$B$2 -> Mae Na Rua | D128: 489.438 | E128: 1592470.1 | F128: 10042.453 | G128: 15019.2 | H128: 0 | I128: 0 | J128: 0 | K128: 705.40466 | L128: 303.19402 | N128: 0 | O128: 0 | P128: 0
A129: 45966 | B129: =Config!$B$3 -> 07:00 | C129: =Config!$B$2 -> Mae Na Rua | D129: 489.451 | E129: 1598455.5 | F129: 16504.948 | G129: 15019.2 | H129: 0 | I129: 18.4 | J129: 5509.2134 | K129: 706.1075 | L129: 303.5078 | M129: 1 | N129: 0 | O129: 0 | P129: 7.609
A130: 45967 | B130: =Config!$B$3 -> 07:00 | C130: =Config!$B$2 -> Mae Na Rua | D130: 489.457 | E130: 1598455.5 | F130: 15909.05 | G130: 15019.2 | H130: 0 | I130: 0.4 | J130: 119.76551 | K130: 706.1075 | L130: 303.5078 | N130: 0 | O130: 7.609 | P130: 0
A131: 45968 | B131: =Config!$B$3 -> 07:00 | C131: =Config!$B$2 -> Mae Na Rua | D131: 489.445 | E131: 1595462 | F131: 4769.2512 | G131: 6753.6 | H131: 0 | I131: 0 | J131: 0 | K131: 705.75634 | L131: 303.35102 | N131: 7.609 | O131: 0 | P131: 0.005
A132: 45969 | B132: =Config!$B$3 -> 07:00 | C132: =Config!$B$2 -> Mae Na Rua | D132: 489.464 | E132: 1601450.3 | F132: 41386.163 | G132: 696.6 | H132: 33810.936 | I132: 0.4 | J132: 119.82517 | K132: 706.45927 | L132: 303.66483 | N132: 0 | O132: 0.005 | P132: 0
A133: 45970 | B133: =Config!$B$3 -> 07:00 | C133: =Config!$B$2 -> Mae Na Rua | D133: 489.677 | E133: 1664741.7 | F133: 324364.26 | G133: 0 | H133: 272915.63 | I133: 42.4 | J133: 12866.019 | K133: 715.61164 | L133: 307.71452 | N133: 0.005 | O133: 0 | P133: 0
A134: 45971 | B134: =Config!$B$3 -> 07:00 | C134: =Config!$B$2 -> Mae Na Rua | D134: 489.721 | E134: 1679932.8 | F134: 368655.76 | G134: 0 | H134: 355298.22 | I134: 9.4 | J134: 2859.5739 | K134: 717.41842 | L134: 308.52438 | N134: 0 | O134: 0 | P134: 0.071
A135: 45972 | B135: =Config!$B$3 -> 07:00 | C135: =Config!$B$2 -> Mae Na Rua | D135: 489.715 | E135: 1676891.5 | F135: 323848.51 | G135: 0 | H135: 325864.48 | I135: 0 | J135: 0 | K135: 717.05315 | L135: 308.36072 | N135: 0 | O135: 0.071 | P135: 0.0006
A136: 45973 | B136: =Config!$B$3 -> 07:00 | C136: =Config!$B$2 -> Mae Na Rua | D136: 489.702 | E136: 1673851.7 | F136: 280267.58 | G136: 0 | H136: 282282.41 | I136: 0 | J136: 0 | K136: 716.68994 | L136: 308.19794 | M136: 1 | N136: 0.071 | O136: 0.0006 | P136: 2.391
A137: 45974 | B137: =Config!$B$3 -> 07:00 | C137: =Config!$B$2 -> Mae Na Rua | D137: 489.68298 | E137: 1667776.8 | F137: 238079.59 | G137: 0 | H137: 243130.66 | I137: 0 | J137: 0 | K137: 715.96901 | L137: 307.87476 | N137: 0.0006 | O137: 2.391 | P137: 0
A138: 45975 | B138: =Config!$B$3 -> 07:00 | C138: =Config!$B$2 -> Mae Na Rua | D138: 489.671 | E138: 1664741.7 | F138: 213597.8 | G138: 0 | H138: 215609.64 | I138: 0 | J138: 0 | K138: 715.61164 | L138: 307.71452 | N138: 2.391 | O138: 0 | P138: 0
A139: 45976 | B139: =Config!$B$3 -> 07:00 | C139: =Config!$B$2 -> Mae Na Rua | D139: 489.664 | E139: 1661708 | F139: 192495.63 | G139: 0 | H139: 194506.47 | I139: 0 | J139: 0 | K139: 715.25615 | L139: 307.55509 | N139: 0 | O139: 0 | P139: 0
A140: 45977 | B140: =Config!$B$3 -> 07:00 | C140: =Config!$B$2 -> Mae Na Rua | D140: 489.658 | E140: 1658675.8 | F140: 175733.51 | G140: 0 | H140: 177743.43 | I140: 0 | J140: 0 | K140: 714.90163 | L140: 307.39611 | N140: 0 | O140: 0 | P140: 0
A141: 45978 | B141: =Config!$B$3 -> 07:00 | C141: =Config!$B$2 -> Mae Na Rua | D141: 489.65698 | E141: 1658675.8 | F141: 177813.59 | G141: 0 | H141: 176791.29 | I141: 0 | J141: 0 | K141: 714.90163 | L141: 307.39611 | N141: 0 | O141: 0 | P141: 0
A142: 45979 | B142: =Config!$B$3 -> 07:00 | C142: =Config!$B$2 -> Mae Na Rua | D142: 489.727 | E142: 1679932.8 | F142: 478550.43 | G142: 0 | H142: 468800.89 | I142: 41.2 | J142: 12533.452 | K142: 717.41842 | L142: 308.52438 | N142: 0 | O142: 0 | P142: 0
A143: 45980 | B143: =Config!$B$3 -> 07:00 | C143: =Config!$B$2 -> Mae Na Rua | D143: 489.857 | E143: 1719668.7 | F143: 957422.96 | G143: 0 | H143: 926241.01 | I143: 31.2 | J143: 9590.6596 | K143: 724.92476 | L143: 311.82497 | N143: 0 | O143: 0 | P143: 0
A144: 45981 | B144: =Config!$B$3 -> 07:00 | C144: =Config!$B$2 -> Mae Na Rua | D144: 489.88998 | E144: 1728897.7 | F144: 893123.03 | G144: 0 | H144: 887904.94 | I144: 16.4 | J144: 5049.2978 | K144: 726.08287 | L144: 312.34498 | N144: 0 | O144: 0 | P144: 0.076
A145: 45982 | B145: =Config!$B$3 -> 07:00 | C145: =Config!$B$2 -> Mae Na Rua | D145: 489.818 | E145: 1707386.4 | F145: 612855.68 | G145: 0 | H145: 633332.49 | I145: 0 | J145: 0 | K145: 723.34769 | L145: 311.1185 | N145: 0 | O145: 0.076 | P145: 0.454
A146: 45983 | B146: =Config!$B$3 -> 07:00 | C146: =Config!$B$2 -> Mae Na Rua | D146: 489.774 | E146: 1695162.9 | F146: 490683.85 | G146: 0 | H146: 501878.76 | I146: 0 | J146: 0 | K146: 719.27346 | L146: 309.35509 | N146: 0.076 | O146: 0.454 | P146: 0.044
A147: 45984 | B147: =Config!$B$3 -> 07:00 | C147: =Config!$B$2 -> Mae Na Rua | D147: 489.754 | E147: 1689066.1 | F147: 433718.87 | G147: 0 | H147: 438788.11 | I147: 0 | J147: 0 | K147: 718.52576 | L147: 309.02034 | N147: 0.454 | O147: 0.044 | P147: 0
A148: 45985 | B148: =Config!$B$3 -> 07:00 | C148: =Config!$B$2 -> Mae Na Rua | D148: 489.734 | E148: 1682975.7 | F148: 379498.75 | G148: 0 | H148: 384562.69 | I148: 0 | J148: 0 | K148: 717.7856 | L148: 308.68887 | N148: 0.044 | O148: 0 | P148: 0.00015
A149: 45986 | B149: =Config!$B$3 -> 07:00 | C149: =Config!$B$2 -> Mae Na Rua | D149: 489.721 | E149: 1679932.8 | F149: 345857.7 | G149: 0 | H149: 347874.57 | I149: 0 | J149: 0 | K149: 717.41842 | L149: 308.52438 | N149: 0 | O149: 0.00015 | P149: 0.063
A150: 45987 | B150: =Config!$B$3 -> 07:00 | C150: =Config!$B$2 -> Mae Na Rua | D150: 489.70898 | E150: 1673851.7 | F150: 310615.12 | G150: 0 | H150: 315671.33 | I150: 0 | J150: 0 | K150: 716.68994 | L150: 308.19794 | M150: 1 | N150: 0.00015 | O150: 0.063 | P150: 8.986
A151: 45988 | B151: =Config!$B$3 -> 07:00 | C151: =Config!$B$2 -> Mae Na Rua | D151: 489.697 | E151: 1670813.5 | F151: 288864.7 | G151: 0 | H151: 290878.59 | I151: 0 | J151: 0 | K151: 716.32846 | L151: 308.03591 | N151: 0.063 | O151: 8.986 | P151: 0.081
A152: 45989 | B152: =Config!$B$3 -> 07:00 | C152: =Config!$B$2 -> Mae Na Rua | D152: 489.691 | E152: 1670813.5 | F152: 272042.76 | G152: 0 | H152: 271018.4 | I152: 0 | J152: 0 | K152: 716.32846 | L152: 308.03591 | N152: 8.986 | O152: 0.081 | P152: 0
A153: 45990 | B153: =Config!$B$3 -> 07:00 | C153: =Config!$B$2 -> Mae Na Rua | D153: 489.684 | E153: 1667776.8 | F153: 252600.34 | G153: 0 | H153: 254613.15 | I153: 0 | J153: 0 | K153: 715.96901 | L153: 307.87476 | N153: 0.081 | O153: 0 | P153: 0
A154: 45991 | B154: =Config!$B$3 -> 07:00 | C154: =Config!$B$2 -> Mae Na Rua | D154: 489.684 | E154: 1667776.8 | F154: 244914.35 | G154: 0 | H154: 243890.5 | I154: 0 | J154: 0 | K154: 715.96901 | L154: 307.87476 | N154: 0 | O154: 0 | P154: 0
...

Sheet Training_Ready
A1: Date | B1: Q_in_t (m³/day) | C1: Water_Level_t (m) | D1: Storage_S_t (m³) | E1: DeltaS_t (m³/day) | F1: %Full_t | G1: Rain_obs_t (mm) | H1: API_t (mm) | I1: DOY | J1: DOY_sin | K1: DOY_cos | L1: Q_lag1 (m³/day) | M1: Q_lag2 (m³/day) | N1: Q_lag3 (m³/day) | O1: Q_lag7 (m³/day) | P1: Q_lag14 (m³/day) | Q1: Rain_obs_sum3 (mm) | R1: Rain_obs_sum7 (mm) | S1: Rain_obs_sum14 (mm) | T1: Q_mean_3d | U1: Outflow_lag1 (m³/day) | V1: Spill_lag1 (m³/day) | W1: Outflow_lag2 (m³/day) | X1: Spill_lag2 (m³/day) | Y1: Outflow_lag3 (m³/day) | Z1: Spill_lag3 (m³/day) | AA1: Rain_fcst_d1 (mm) | AB1: Rain_fcst_d2 (mm) | AC1: Rain_fcst_d3 (mm) | AD1: Rain_fcst_sum1_3 (mm) | AE1: Rain_fcst_max1_3 (mm) | AF1: y1=Q_in_t+1 (m³/day) | AG1: y2=Q_in_t+2 (m³/day) | AH1: y3=Q_in_t+3 (m³/day)
A2: =Daily_Input!A2 -> 45839 | B2: =Daily_Input!F2 -> 16137.621 | C2: =Daily_Input!D2 -> 489.518 | D2: =Daily_Input!E2 -> 1616447.3 | F2: =IFERROR(Daily_Input!E2/Config!$B$4,"") -> 0.99445299 | G2: =Daily_Input!I2 -> 0 | H2: =IF(A2="","",IF(ROW()=2,G2,Config!$B$5*H1+G2)) -> 0 | I2: =IF(A2="","",A2-DATE(YEAR(A2),1,0)) -> 182 | J2: =IF(I2="","",SIN(2*PI()*I2/Config!$B$6)) -> 0.0086069969 | K2: =IF(I2="","",COS(2*PI()*I2/Config!$B$6)) -> -0.99996296 | L2: =IF(ROW()<=2+0,"",INDEX(Daily_Input!$F:$F,ROW()-1)) | M2: =IF(ROW()<=2+1,"",INDEX(Daily_Input!$F:$F,ROW()-2)) | N2: =IF(ROW()<=2+2,"",INDEX(Daily_Input!$F:$F,ROW()-3)) | O2: =IF(ROW()<=2+6,"",INDEX([1]Daily_Input!$F:$F,ROW()-7)) | P2: =IF(ROW()<=2+13,"",INDEX([1]Daily_Input!$F:$F,ROW()-14)) | R2: =IF(ROW()<=8,"",SUM([1]Daily_Input!#REF!)) | S2: =IF(ROW()<=15,"",SUM([1]Daily_Input!#REF!)) | U2: =IF(ROW()<=2+0,"",INDEX(Daily_Input!$G:$G,ROW()-1)) | V2: =IF(ROW()<=2+0,"",INDEX(Daily_Input!$H:$H,ROW()-1)) | W2: =IF(ROW()<=2+1,"",INDEX(Daily_Input!$G:$G,ROW()-2)) | X2: =IF(ROW()<=2+1,"",INDEX(Daily_Input!$H:$H,ROW()-2)) | Y2: =IF(ROW()<=2+2,"",INDEX(Daily_Input!$G:$G,ROW()-3)) | Z2: =IF(ROW()<=2+2,"",INDEX(Daily_Input!$H:$H,ROW()-3)) | AA2: =Daily_Input!N2 -> 13.673 | AB2: =Daily_Input!O2 -> 6.699 | AC2: =Daily_Input!P2 -> 4.328 | AD2: =IF(A2="","",SUM(AA2:AC2)) -> 24.7 | AE2: =IF(A2="","",MAX(AA2:AC2)) -> 13.673 | AF2: =IF(A2="","",IFERROR(INDEX(Daily_Input!$F:$F,ROW()+1),"")) -> 18000.43 | AG2: =IF(A2="","",IFERROR(INDEX(Daily_Input!$F:$F,ROW()+2),"")) -> 16551.136 | AH2: =IF(A2="","",IFERROR(INDEX(Daily_Input!$F:$F,ROW()+3),"")) -> 21950.322
A3: =Daily_Input!A3 -> 45840 | B3: =Daily_Input!F3 -> 18000.43 | C3: =Daily_Input!D3 -> 489.524 | D3: =Daily_Input!E3 -> 1619451.3 | E3: {=IF(ROW()=2,"",INDEX(Daily_Input!$E:$E,ROW())-INDEX(Daily_Input!$E:$E,ROW()-1))} -> 3004.017 | F3: =IFERROR(Daily_Input!E3/Config!$B$4,"") -> 0.99630109 | G3: =Daily_Input!I3 -> 3.8 | H3: =IF(A3="","",IF(ROW()=2,G3,Config!$B$5*H2+G3)) -> 3.8 | I3: =IF(A3="","",A3-DATE(YEAR(A3),1,0)) -> 183 | J3: =IF(I3="","",SIN(2*PI()*I3/Config!$B$6)) -> -0.0086069969 | K3: =IF(I3="","",COS(2*PI()*I3/Config!$B$6)) -> -0.99996296 | L3: =IF(ROW()<=2+0,"",INDEX(Daily_Input!$F:$F,ROW()-1)) -> 16137.621 | M3: =IF(ROW()<=2+1,"",INDEX(Daily_Input!$F:$F,ROW()-2)) | N3: =IF(ROW()<=2+2,"",INDEX(Daily_Input!$F:$F,ROW()-3)) | O3: =IF(ROW()<=2+6,"",INDEX([1]Daily_Input!$F:$F,ROW()-7)) | P3: =IF(ROW()<=2+13,"",INDEX([1]Daily_Input!$F:$F,ROW()-14)) | R3: =IF(ROW()<=8,"",SUM([1]Daily_Input!#REF!)) | S3: =IF(ROW()<=15,"",SUM([1]Daily_Input!#REF!)) | U3: =IF(ROW()<=2+0,"",INDEX(Daily_Input!$G:$G,ROW()-1)) -> 15019.2 | V3: =IF(ROW()<=2+0,"",INDEX(Daily_Input!$H:$H,ROW()-1)) -> 0 | W3: =IF(ROW()<=2+1,"",INDEX(Daily_Input!$G:$G,ROW()-2)) | X3: =IF(ROW()<=2+1,"",INDEX(Daily_Input!$H:$H,ROW()-2)) | Y3: =IF(ROW()<=2+2,"",INDEX(Daily_Input!$G:$G,ROW()-3)) | Z3: =IF(ROW()<=2+2,"",INDEX(Daily_Input!$H:$H,ROW()-3)) | AA3: =Daily_Input!N3 -> 6.699 | AB3: =Daily_Input!O3 -> 4.328 | AC3: =Daily_Input!P3 -> 10.32 | AD3: =IF(A3="","",SUM(AA3:AC3)) -> 21.347 | AE3: =IF(A3="","",MAX(AA3:AC3)) -> 10.32 | AF3: =IF(A3="","",IFERROR(INDEX(Daily_Input!$F:$F,ROW()+1),"")) -> 16551.136 | AG3: =IF(A3="","",IFERROR(INDEX(Daily_Input!$F:$F,ROW()+2),"")) -> 21950.322 | AH3: =IF(A3="","",IFERROR(INDEX(Daily_Input!$F:$F,ROW()+3),"")) -> 22689.828
A4: =Daily_Input!A4 -> 45841 | B4: =Daily_Input!F4 -> 16551.136 | C4: =Daily_Input!D4 -> 489.524 | D4: =Daily_Input!E4 -> 1619451.3 | E4: {=IF(ROW()=2,"",INDEX(Daily_Input!$E:$E,ROW())-INDEX(Daily_Input!$E:$E,ROW()-1))} -> 0 | F4: =IFERROR(Daily_Input!E4/Config!$B$4,"") -> 0.99630109 | G4: =Daily_Input!I4 -> 0 | H4: =IF(A4="","",IF(ROW()=2,G4,Config!$B$5*H3+G4)) -> 3.61 | I4: =IF(A4="","",A4-DATE(YEAR(A4),1,0)) -> 184 | J4: =IF(I4="","",SIN(2*PI()*I4/Config!$B$6)) -> -0.02581844 | K4: =IF(I4="","",COS(2*PI()*I4/Config!$B$6)) -> -0.99966665 | L4: =IF(ROW()<=2+0,"",INDEX(Daily_Input!$F:$F,ROW()-1)) -> 18000.43 | M4: =IF(ROW()<=2+1,"",INDEX(Daily_Input!$F:$F,ROW()-2)) -> 16137.621 | N4: =IF(ROW()<=2+2,"",INDEX(Daily_Input!$F:$F,ROW()-3)) | O4: =IF(ROW()<=2+6,"",INDEX([1]Daily_Input!$F:$F,ROW()-7)) | P4: =IF(ROW()<=2+13,"",INDEX([1]Daily_Input!$F:$F,ROW()-14)) | R4: =IF(ROW()<=8,"",SUM([1]Daily_Input!#REF!)) | S4: =IF(ROW()<=15,"",SUM([1]Daily_Input!#REF!)) | U4: =IF(ROW()<=2+0,"",INDEX(Daily_Input!$G:$G,ROW()-1)) -> 15019.2 | V4: =IF(ROW()<=2+0,"",INDEX(Daily_Input!$H:$H,ROW()-1)) -> 0 | W4: =IF(ROW()<=2+1,"",INDEX(Daily_Input!$G:$G,ROW()-2)) -> 15019.2 | X4: =IF(ROW()<=2+1,"",INDEX(Daily_Input!$H:$H,ROW()-2)) -> 0 | Y4: =IF(ROW()<=2+2,"",INDEX(Daily_Input!$G:$G,ROW()-3)) | Z4: =IF(ROW()<=2+2,"",INDEX(Daily_Input!$H:$H,ROW()-3)) | AA4: =Daily_Input!N4 -> 4.328 | AB4: =Daily_Input!O4 -> 10.32 | AC4: =Daily_Input!P4 -> 4.29 | AD4: =IF(A4="","",SUM(AA4:AC4)) -> 18.938 | AE4: =IF(A4="","",MAX(AA4:AC4)) -> 10.32 | AF4: =IF(A4="","",IFERROR(INDEX(Daily_Input!$F:$F,ROW()+1),"")) -> 21950.322 | AG4: =IF(A4="","",IFERROR(INDEX(Daily_Input!$F:$F,ROW()+2),"")) -> 22689.828 | AH4: =IF(A4="","",IFERROR(INDEX(Daily_Input!$F:$F,ROW()+3),"")) -> 41715.189
A5: =Daily_Input!A5 -> 45842 | B5: =Daily_Input!F5 -> 21950.322 | C5: =Daily_Input!D5 -> 489.557 | D5: =Daily_Input!E5 -> 1628472.3 | E5: {=IF(ROW()=2,"",INDEX(Daily_Input!$E:$E,ROW())-INDEX(Daily_Input!$E:$E,ROW()-1))} -> 9020.9887 | F5: =IFERROR(Daily_Input!E5/Config!$B$4,"") -> 1.0018509 | G5: =Daily_Input!I5 -> 30.2 | H5: =IF(A5="","",IF(ROW()=2,G5,Config!$B$5*H4+G5)) -> 33.6295 | I5: =IF(A5="","",A5-DATE(YEAR(A5),1,0)) -> 185 | J5: =IF(I5="","",SIN(2*PI()*I5/Config!$B$6)) -> -0.043022233 | K5: =IF(I5="","",COS(2*PI()*I5/Config!$B$6)) -> -0.99907412 | L5: =IF(ROW()<=2+0,"",INDEX(Daily_Input!$F:$F,ROW()-1)) -> 16551.136 | M5: =IF(ROW()<=2+1,"",INDEX(Daily_Input!$F:$F,ROW()-2)) -> 18000.43 | N5: =IF(ROW()<=2+2,"",INDEX(Daily_Input!$F:$F,ROW()-3)) -> 16137.621 | O5: =IF(ROW()<=2+6,"",INDEX([1]Daily_Input!$F:$F,ROW()-7)) | P5: =IF(ROW()<=2+13,"",INDEX([1]Daily_Input!$F:$F,ROW()-14)) | Q5: =IF(ROW()<=4,"",SUM(INDEX(Daily_Input!$I:$I,ROW()-2):INDEX(Daily_Input!$I:$I,ROW()))) -> 34 | R5: =IF(ROW()<=8,"",SUM([1]Daily_Input!#REF!)) | S5: =IF(ROW()<=15,"",SUM([1]Daily_Input!#REF!)) | T5: =IF(ROW()<=4,"",AVERAGE(INDEX(Daily_Input!$F:$F,ROW()-2):INDEX(Daily_Input!$F:$F,ROW()))) -> 18833.963 | U5: =IF(ROW()<=2+0,"",INDEX(Daily_Input!$G:$G,ROW()-1)) -> 15019.2 | V5: =IF(ROW()<=2+0,"",INDEX(Daily_Input!$H:$H,ROW()-1)) -> 412.94112 | W5: =IF(ROW()<=2+1,"",INDEX(Daily_Input!$G:$G,ROW()-2)) -> 15019.2 | X5: =IF(ROW()<=2+1,"",INDEX(Daily_Input!$H:$H,ROW()-2)) -> 0 | Y5: =IF(ROW()<=2+2,"",INDEX(Daily_Input!$G:$G,ROW()-3)) -> 15019.2 | Z5: =IF(ROW()<=2+2,"",INDEX(Daily_Input!$H:$H,ROW()-3)) -> 0 | AA5: =Daily_Input!N5 -> 10.32 | AB5: =Daily_Input!O5 -> 4.29 | AC5: =Daily_Input!P5 -> 1.138 | AD5: =IF(A5="","",SUM(AA5:AC5)) -> 15.748 | AE5: =IF(A5="","",MAX(AA5:AC5)) -> 10.32 | AF5: =IF(A5="","",IFERROR(INDEX(Daily_Input!$F:$F,ROW()+1),"")) -> 22689.828 | AG5: =IF(A5="","",IFERROR(INDEX(Daily_Input!$F:$F,ROW()+2),"")) -> 41715.189 | AH5: =IF(A5="","",IFERROR(INDEX(Daily_Input!$F:$F,ROW()+3),"")) -> 41682.058
A6: =Daily_Input!A6 -> 45843 | B6: =Daily_Input!F6 -> 22689.828 | C6: =Daily_Input!D6 -> 489.557 | D6: =Daily_Input!E6 -> 1628472.3 | E6: {=IF(ROW()=2,"",INDEX(Daily_Input!$E:$E,ROW())-INDEX(Daily_Input!$E:$E,ROW()-1))} -> 0 | F6: =IFERROR(Daily_Input!E6/Config!$B$4,"") -> 1.0018509 | G6: =Daily_Input!I6 -> 0.4 | H6: =IF(A6="","",IF(ROW()=2,G6,Config!$B$5*H5+G6)) -> 32.348025 | I6: =IF(A6="","",A6-DATE(YEAR(A6),1,0)) -> 186 | J6: =IF(I6="","",SIN(2*PI()*I6/Config!$B$6)) -> -0.060213277 | K6: =IF(I6="","",COS(2*PI()*I6/Config!$B$6)) -> -0.99818553 | L6: =IF(ROW()<=2+0,"",INDEX(Daily_Input!$F:$F,ROW()-1)) -> 21950.322 | M6: =IF(ROW()<=2+1,"",INDEX(Daily_Input!$F:$F,ROW()-2)) -> 16551.136 | N6: =IF(ROW()<=2+2,"",INDEX(Daily_Input!$F:$F,ROW()-3)) -> 18000.43 | O6: =IF(ROW()<=2+6,"",INDEX([1]Daily_Input!$F:$F,ROW()-7)) | P6: =IF(ROW()<=2+13,"",INDEX([1]Daily_Input!$F:$F,ROW()-14)) | Q6: =IF(ROW()<=4,"",SUM(INDEX(Daily_Input!$I:$I,ROW()-2):INDEX(Daily_Input!$I:$I,ROW()))) -> 30.6 | R6: =IF(ROW()<=8,"",SUM([1]Daily_Input!#REF!)) | S6: =IF(ROW()<=15,"",SUM([1]Daily_Input!#REF!)) | T6: =IF(ROW()<=4,"",AVERAGE(INDEX(Daily_Input!$F:$F,ROW()-2):INDEX(Daily_Input!$F:$F,ROW()))) -> 20397.095 | U6: =IF(ROW()<=2+0,"",INDEX(Daily_Input!$G:$G,ROW()-1)) -> 15019.2 | V6: =IF(ROW()<=2+0,"",INDEX(Daily_Input!$H:$H,ROW()-1)) -> 5877.4746 | W6: =IF(ROW()<=2+1,"",INDEX(Daily_Input!$G:$G,ROW()-2)) -> 15019.2 | X6: =IF(ROW()<=2+1,"",INDEX(Daily_Input!$H:$H,ROW()-2)) -> 412.94112 | Y6: =IF(ROW()<=2+2,"",INDEX(Daily_Input!$G:$G,ROW()-3)) -> 15019.2 | Z6: =IF(ROW()<=2+2,"",INDEX(Daily_Input!$H:$H,ROW()-3)) -> 0 | AA6: =Daily_Input!N6 -> 4.29 | AB6: =Daily_Input!O6 -> 1.138 | AC6: =Daily_Input!P6 -> 13.004 | AD6: =IF(A6="","",SUM(AA6:AC6)) -> 18.432 | AE6: =IF(A6="","",MAX(AA6:AC6)) -> 13.004 | AF6: =IF(A6="","",IFERROR(INDEX(Daily_Input!$F:$F,ROW()+1),"")) -> 41715.189 | AG6: =IF(A6="","",IFERROR(INDEX(Daily_Input!$F:$F,ROW()+2),"")) -> 41682.058 | AH6: =IF(A6="","",IFERROR(INDEX(Daily_Input!$F:$F,ROW()+3),"")) -> 38705.212
A7: =Daily_Input!A7 -> 45844 | B7: =Daily_Input!F7 -> 41715.189 | C7: =Daily_Input!D7 -> 489.577 | D7: =Daily_Input!E7 -> 1634494 | E7: {=IF(ROW()=2,"",INDEX(Daily_Input!$E:$E,ROW())-INDEX(Daily_Input!$E:$E,ROW()-1))} -> 6021.7108 | F7: =IFERROR(Daily_Input!E7/Config!$B$4,"") -> 1.0055555 | G7: =Daily_Input!I7 -> 17.2 | H7: =IF(A7="","",IF(ROW()=2,G7,Config!$B$5*H6+G7)) -> 47.930624 | I7: =IF(A7="","",A7-DATE(YEAR(A7),1,0)) -> 187 | J7: =IF(I7="","",SIN(2*PI()*I7/Config!$B$6)) -> -0.077386479 | K7: =IF(I7="","",COS(2*PI()*I7/Config!$B$6)) -> -0.99700117 | L7: =IF(ROW()<=2+0,"",INDEX(Daily_Input!$F:$F,ROW()-1)) -> 22689.828 | M7: =IF(ROW()<=2+1,"",INDEX(Daily_Input!$F:$F,ROW()-2)) -> 21950.322 | N7: =IF(ROW()<=2+2,"",INDEX(Daily_Input!$F:$F,ROW()-3)) -> 16551.136 | O7: =IF(ROW()<=2+6,"",INDEX([1]Daily_Input!$F:$F,ROW()-7)) | P7: =IF(ROW()<=2+13,"",INDEX([1]Daily_Input!$F:$F,ROW()-14)) | Q7: =IF(ROW()<=4,"",SUM(INDEX(Daily_Input!$I:$I,ROW()-2):INDEX(Daily_Input!$I:$I,ROW()))) -> 47.8 | R7: =IF(ROW()<=8,"",SUM([1]Daily_Input!#REF!)) | S7: =IF(ROW()<=15,"",SUM([1]Daily_Input!#REF!)) | T7: =IF(ROW()<=4,"",AVERAGE(INDEX(Daily_Input!$F:$F,ROW()-2):INDEX(Daily_Input!$F:$F,ROW()))) -> 28785.113 | U7: =IF(ROW()<=2+0,"",INDEX(Daily_Input!$G:$G,ROW()-1)) -> 15019.2 | V7: =IF(ROW()<=2+0,"",INDEX(Daily_Input!$H:$H,ROW()-1)) -> 6670.2723 | W7: =IF(ROW()<=2+1,"",INDEX(Daily_Input!$G:$G,ROW()-2)) -> 15019.2 | X7: =IF(ROW()<=2+1,"",INDEX(Daily_Input!$H:$H,ROW()-2)) -> 5877.4746 | Y7: =IF(ROW()<=2+2,"",INDEX(Daily_Input!$G:$G,ROW()-3)) -> 15019.2 | Z7: =IF(ROW()<=2+2,"",INDEX(Daily_Input!$H:$H,ROW()-3)) -> 412.94112 | AA7: =Daily_Input!N7 -> 1.138 | AB7: =Daily_Input!O7 -> 13.004 | AC7: =Daily_Input!P7 -> 9.394 | AD7: =IF(A7="","",SUM(AA7:AC7)) -> 23.536 | AE7: =IF(A7="","",MAX(AA7:AC7)) -> 13.004 | AF7: =IF(A7="","",IFERROR(INDEX(Daily_Input!$F:$F,ROW()+1),"")) -> 41682.058 | AG7: =IF(A7="","",IFERROR(INDEX(Daily_Input!$F:$F,ROW()+2),"")) -> 38705.212 | AH7: =IF(A7="","",IFERROR(INDEX(Daily_Input!$F:$F,ROW()+3),"")) -> 33915.235
A8: =Daily_Input!A8 -> 45845 | B8: =Daily_Input!F8 -> 41682.058 | C8: =Daily_Input!D8 -> 489.577 | D8: =Daily_Input!E8 -> 1634494 | E8: {=IF(ROW()=2,"",INDEX(Daily_Input!$E:$E,ROW())-INDEX(Daily_Input!$E:$E,ROW()-1))} -> 0 | F8: =IFERROR(Daily_Input!E8/Config!$B$4,"") -> 1.0055555 | G8: =Daily_Input!I8 -> 0 | H8: =IF(A8="","",IF(ROW()=2,G8,Config!$B$5*H7+G8)) -> 45.534093 | I8: =IF(A8="","",A8-DATE(YEAR(A8),1,0)) -> 188 | J8: =IF(I8="","",SIN(2*PI()*I8/Config!$B$6)) -> -0.09453675 | K8: =IF(I8="","",COS(2*PI()*I8/Config!$B$6)) -> -0.99552137 | L8: =IF(ROW()<=2+0,"",INDEX(Daily_Input!$F:$F,ROW()-1)) -> 41715.189 | M8: =IF(ROW()<=2+1,"",INDEX(Daily_Input!$F:$F,ROW()-2)) -> 22689.828 | N8: =IF(ROW()<=2+2,"",INDEX(Daily_Input!$F:$F,ROW()-3)) -> 21950.322 | O8: =IF(ROW()<=2+6,"",INDEX([1]Daily_Input!$F:$F,ROW()-7)) | P8: =IF(ROW()<=2+13,"",INDEX([1]Daily_Input!$F:$F,ROW()-14)) | Q8: =IF(ROW()<=4,"",SUM(INDEX(Daily_Input!$I:$I,ROW()-2):INDEX(Daily_Input!$I:$I,ROW()))) -> 17.6 | R8: =IF(ROW()<=8,"",SUM([1]Daily_Input!#REF!)) | S8: =IF(ROW()<=15,"",SUM([1]Daily_Input!#REF!)) | T8: =IF(ROW()<=4,"",AVERAGE(INDEX(Daily_Input!$F:$F,ROW()-2):INDEX(Daily_Input!$F:$F,ROW()))) -> 35362.358 | U8: =IF(ROW()<=2+0,"",INDEX(Daily_Input!$G:$G,ROW()-1)) -> 15019.2 | V8: =IF(ROW()<=2+0,"",INDEX(Daily_Input!$H:$H,ROW()-1)) -> 24733.704 | W8: =IF(ROW()<=2+1,"",INDEX(Daily_Input!$G:$G,ROW()-2)) -> 15019.2 | X8: =IF(ROW()<=2+1,"",INDEX(Daily_Input!$H:$H,ROW()-2)) -> 6670.2723 | Y8: =IF(ROW()<=2+2,"",INDEX(Daily_Input!$G:$G,ROW()-3)) -> 15019.2 | Z8: =IF(ROW()<=2+2,"",INDEX(Daily_Input!$H:$H,ROW()-3)) -> 5877.4746 | AA8: =Daily_Input!N8 -> 13.004 | AB8: =Daily_Input!O8 -> 9.394 | AC8: =Daily_Input!P8 -> 1.67 | AD8: =IF(A8="","",SUM(AA8:AC8)) -> 24.068 | AE8: =IF(A8="","",MAX(AA8:AC8)) -> 13.004 | AF8: =IF(A8="","",IFERROR(INDEX(Daily_Input!$F:$F,ROW()+1),"")) -> 38705.212 | AG8: =IF(A8="","",IFERROR(INDEX(Daily_Input!$F:$F,ROW()+2),"")) -> 33915.235 | AH8: =IF(A8="","",IFERROR(INDEX(Daily_Input!$F:$F,ROW()+3),"")) -> 16680.986
A9: =Daily_Input!A9 -> 45846 | B9: =Daily_Input!F9 -> 38705.212 | C9: =Daily_Input!D9 -> 489.577 | D9: =Daily_Input!E9 -> 1634494 | E9: {=IF(ROW()=2,"",INDEX(Daily_Input!$E:$E,ROW())-INDEX(Daily_Input!$E:$E,ROW()-1))} -> 0 | F9: =IFERROR(Daily_Input!E9/Config!$B$4,"") -> 1.0055555 | G9: =Daily_Input!I9 -> 0 | H9: =IF(A9="","",IF(ROW()=2,G9,Config!$B$5*H8+G9)) -> 43.257388 | I9: =IF(A9="","",A9-DATE(YEAR(A9),1,0)) -> 189 | J9: =IF(I9="","",SIN(2*PI()*I9/Config!$B$6)) -> -0.11165901 | K9: =IF(I9="","",COS(2*PI()*I9/Config!$B$6)) -> -0.99374658 | L9: =IF(ROW()<=2+0,"",INDEX(Daily_Input!$F:$F,ROW()-1)) -> 41682.058 | M9: =IF(ROW()<=2+1,"",INDEX(Daily_Input!$F:$F,ROW()-2)) -> 41715.189 | N9: =IF(ROW()<=2+2,"",INDEX(Daily_Input!$F:$F,ROW()-3)) -> 22689.828 | O9: =IF(ROW()<=2+6,"",INDEX(Daily_Input!$F:$F,ROW()-7)) -> 16137.621 | P9: =IF(ROW()<=2+13,"",INDEX([1]Daily_Input!$F:$F,ROW()-14)) | Q9: =IF(ROW()<=4,"",SUM(INDEX(Daily_Input!$I:$I,ROW()-2):INDEX(Daily_Input!$I:$I,ROW()))) -> 17.2 | R9: =IF(ROW()<=8,"",SUM(INDEX(Daily_Input!$I:$I,ROW()-6):INDEX(Daily_Input!$I:$I,ROW()))) -> 51.6 | S9: =IF(ROW()<=15,"",SUM([1]Daily_Input!#REF!)) | T9: =IF(ROW()<=4,"",AVERAGE(INDEX(Daily_Input!$F:$F,ROW()-2):INDEX(Daily_Input!$F:$F,ROW()))) -> 40700.82 | U9: =IF(ROW()<=2+0,"",INDEX(Daily_Input!$G:$G,ROW()-1)) -> 15019.2 | V9: =IF(ROW()<=2+0,"",INDEX(Daily_Input!$H:$H,ROW()-1)) -> 25540.965 | W9: =IF(ROW()<=2+1,"",INDEX(Daily_Input!$G:$G,ROW()-2)) -> 15019.2 | X9: =IF(ROW()<=2+1,"",INDEX(Daily_Input!$H:$H,ROW()-2)) -> 24733.704 | Y9: =IF(ROW()<=2+2,"",INDEX(Daily_Input!$G:$G,ROW()-3)) -> 15019.2 | Z9: =IF(ROW()<=2+2,"",INDEX(Daily_Input!$H:$H,ROW()-3)) -> 6670.2723 | AA9: =Daily_Input!N9 -> 9.394 | AB9: =Daily_Input!O9 -> 1.67 | AC9: =Daily_Input!P9 -> 10.659 | AD9: =IF(A9="","",SUM(AA9:AC9)) -> 21.723 | AE9: =IF(A9="","",MAX(AA9:AC9)) -> 10.659 | AF9: =IF(A9="","",IFERROR(INDEX(Daily_Input!$F:$F,ROW()+1),"")) -> 33915.235 | AG9: =IF(A9="","",IFERROR(INDEX(Daily_Input!$F:$F,ROW()+2),"")) -> 16680.986 | AH9: =IF(A9="","",IFERROR(INDEX(Daily_Input!$F:$F,ROW()+3),"")) -> 9699.6258
A10: =Daily_Input!A10 -> 45847 | B10: =Daily_Input!F10 -> 33915.235 | C10: =Daily_Input!D10 -> 489.57 | D10: =Daily_Input!E10 -> 1634494 | E10: {=IF(ROW()=2,"",INDEX(Daily_Input!$E:$E,ROW())-INDEX(Daily_Input!$E:$E,ROW()-1))} -> 0 | F10: =IFERROR(Daily_Input!E10/Config!$B$4,"") -> 1.0055555 | G10: =Daily_Input!I10 -> 0 | H10: =IF(A10="","",IF(ROW()=2,G10,Config!$B$5*H9+G10)) -> 41.094519 | I10: =IF(A10="","",A10-DATE(YEAR(A10),1,0)) -> 190 | J10: =IF(I10="","",SIN(2*PI()*I10/Config!$B$6)) -> -0.12874818 | K10: =IF(I10="","",COS(2*PI()*I10/Config!$B$6)) -> -0.99167732 | L10: =IF(ROW()<=2+0,"",INDEX(Daily_Input!$F:$F,ROW()-1)) -> 38705.212 | M10: =IF(ROW()<=2+1,"",INDEX(Daily_Input!$F:$F,ROW()-2)) -> 41682.058 | N10: =IF(ROW()<=2+2,"",INDEX(Daily_Input!$F:$F,ROW()-3)) -> 41715.189 | O10: =IF(ROW()<=2+6,"",INDEX(Daily_Input!$F:$F,ROW()-7)) -> 18000.43 | P10: =IF(ROW()<=2+13,"",INDEX([1]Daily_Input!$F:$F,ROW()-14)) | Q10: =IF(ROW()<=4,"",SUM(INDEX(Daily_Input!$I:$I,ROW()-2):INDEX(Daily_Input!$I:$I,ROW()))) -> 0 | R10: =IF(ROW()<=8,"",SUM(INDEX(Daily_Input!$I:$I,ROW()-6):INDEX(Daily_Input!$I:$I,ROW()))) -> 47.8 | S10: =IF(ROW()<=15,"",SUM([1]Daily_Input!#REF!)) | T10: =IF(ROW()<=4,"",AVERAGE(INDEX(Daily_Input!$F:$F,ROW()-2):INDEX(Daily_Input!$F:$F,ROW()))) -> 38100.835 | U10: =IF(ROW()<=2+0,"",INDEX(Daily_Input!$G:$G,ROW()-1)) -> 15019.2 | V10: =IF(ROW()<=2+0,"",INDEX(Daily_Input!$H:$H,ROW()-1)) -> 22564.119 | W10: =IF(ROW()<=2+1,"",INDEX(Daily_Input!$G:$G,ROW()-2)) -> 15019.2 | X10: =IF(ROW()<=2+1,"",INDEX(Daily_Input!$H:$H,ROW()-2)) -> 25540.965 | Y10: =IF(ROW()<=2+2,"",INDEX(Daily_Input!$G:$G,ROW()-3)) -> 15019.2 | Z10: =IF(ROW()<=2+2,"",INDEX(Daily_Input!$H:$H,ROW()-3)) -> 24733.704 | AA10: =Daily_Input!N10 -> 1.67 | AB10: =Daily_Input!O10 -> 10.659 | AC10: =Daily_Input!P10 -> 20.48 | AD10: =IF(A10="","",SUM(AA10:AC10)) -> 32.809 | AE10: =IF(A10="","",MAX(AA10:AC10)) -> 20.48 | AF10: =IF(A10="","",IFERROR(INDEX(Daily_Input!$F:$F,ROW()+1),"")) -> 16680.986 | AG10: =IF(A10="","",IFERROR(INDEX(Daily_Input!$F:$F,ROW()+2),"")) -> 9699.6258 | AH10: =IF(A10="","",IFERROR(INDEX(Daily_Input!$F:$F,ROW()+3),"")) -> 20534.223
A11: =Daily_Input!A11 -> 45848 | B11: =Daily_Input!F11 -> 16680.986 | C11: =Daily_Input!D11 -> 489.564 | D11: =Daily_Input!E11 -> 1631482.4 | E11: {=IF(ROW()=2,"",INDEX(Daily_Input!$E:$E,ROW())-INDEX(Daily_Input!$E:$E,ROW()-1))} -> -3011.6213 | F11: =IFERROR(Daily_Input!E11/Config!$B$4,"") -> 1.0037027 | G11: =Daily_Input!I11 -> 8.6 | H11: =IF(A11="","",IF(ROW()=2,G11,Config!$B$5*H10+G11)) -> 47.639793 | I11: =IF(A11="","",A11-DATE(YEAR(A11),1,0)) -> 191 | J11: =IF(I11="","",SIN(2*PI()*I11/Config!$B$6)) -> -0.1457992 | K11: =IF(I11="","",COS(2*PI()*I11/Config!$B$6)) -> -0.9893142 | L11: =IF(ROW()<=2+0,"",INDEX(Daily_Input!$F:$F,ROW()-1)) -> 33915.235 | M11: =IF(ROW()<=2+1,"",INDEX(Daily_Input!$F:$F,ROW()-2)) -> 38705.212 | N11: =IF(ROW()<=2+2,"",INDEX(Daily_Input!$F:$F,ROW()-3)) -> 41682.058 | O11: =IF(ROW()<=2+6,"",INDEX(Daily_Input!$F:$F,ROW()-7)) -> 16551.136 | P11: =IF(ROW()<=2+13,"",INDEX([1]Daily_Input!$F:$F,ROW()-14)) | Q11: =IF(ROW()<=4,"",SUM(INDEX(Daily_Input!$I:$I,ROW()-2):INDEX(Daily_Input!$I:$I,ROW()))) -> 8.6 | R11: =IF(ROW()<=8,"",SUM(INDEX(Daily_Input!$I:$I,ROW()-6):INDEX(Daily_Input!$I:$I,ROW()))) -> 56.4 | S11: =IF(ROW()<=15,"",SUM([1]Daily_Input!#REF!)) | T11: =IF(ROW()<=4,"",AVERAGE(INDEX(Daily_Input!$F:$F,ROW()-2):INDEX(Daily_Input!$F:$F,ROW()))) -> 29767.144 | U11: =IF(ROW()<=2+0,"",INDEX(Daily_Input!$G:$G,ROW()-1)) -> 15019.2 | V11: =IF(ROW()<=2+0,"",INDEX(Daily_Input!$H:$H,ROW()-1)) -> 17774.142 | W11: =IF(ROW()<=2+1,"",INDEX(Daily_Input!$G:$G,ROW()-2)) -> 15019.2 | X11: =IF(ROW()<=2+1,"",INDEX(Daily_Input!$H:$H,ROW()-2)) -> 22564.119 | Y11: =IF(ROW()<=2+2,"",INDEX(Daily_Input!$G:$G,ROW()-3)) -> 15019.2 | Z11: =IF(ROW()<=2+2,"",INDEX(Daily_Input!$H:$H,ROW()-3)) -> 25540.965 | AA11: =Daily_Input!N11 -> 10.659 | AB11: =Daily_Input!O11 -> 20.48 | AC11: =Daily_Input!P11 -> 22.463 | AD11: =IF(A11="","",SUM(AA11:AC11)) -> 53.602 | AE11: =IF(A11="","",MAX(AA11:AC11)) -> 22.463 | AF11: =IF(A11="","",IFERROR(INDEX(Daily_Input!$F:$F,ROW()+1),"")) -> 9699.6258 | AG11: =IF(A11="","",IFERROR(INDEX(Daily_Input!$F:$F,ROW()+2),"")) -> 20534.223 | AH11: =IF(A11="","",IFERROR(INDEX(Daily_Input!$F:$F,ROW()+3),"")) -> 62384.338
A12: =Daily_Input!A12 -> 45849 | B12: =Daily_Input!F12 -> 9699.6258 | C12: =Daily_Input!D12 -> 489.544 | D12: =Daily_Input!E12 -> 1625463.8 | E12: {=IF(ROW()=2,"",INDEX(Daily_Input!$E:$E,ROW())-INDEX(Daily_Input!$E:$E,ROW()-1))} -> -6018.6362 | F12: =IFERROR(Daily_Input!E12/Config!$B$4,"") -> 1 | G12: =Daily_Input!I12 -> 1.4 | H12: =IF(A12="","",IF(ROW()=2,G12,Config!$B$5*H11+G12)) -> 46.657803 | I12: =IF(A12="","",A12-DATE(YEAR(A12),1,0)) -> 192 | J12: =IF(I12="","",SIN(2*PI()*I12/Config!$B$6)) -> -0.16280701 | K12: =IF(I12="","",COS(2*PI()*I12/Config!$B$6)) -> -0.98665793 | L12: =IF(ROW()<=2+0,"",INDEX(Daily_Input!$F:$F,ROW()-1)) -> 16680.986 | M12: =IF(ROW()<=2+1,"",INDEX(Daily_Input!$F:$F,ROW()-2)) -> 33915.235 | N12: =IF(ROW()<=2+2,"",INDEX(Daily_Input!$F:$F,ROW()-3)) -> 38705.212 | O12: =IF(ROW()<=2+6,"",INDEX(Daily_Input!$F:$F,ROW()-7)) -> 21950.322 | P12: =IF(ROW()<=2+13,"",INDEX([1]Daily_Input!$F:$F,ROW()-14)) | Q12: =IF(ROW()<=4,"",SUM(INDEX(Daily_Input!$I:$I,ROW()-2):INDEX(Daily_Input!$I:$I,ROW()))) -> 10 | R12: =IF(ROW()<=8,"",SUM(INDEX(Daily_Input!$I:$I,ROW()-6):INDEX(Daily_Input!$I:$I,ROW()))) -> 27.6 | S12: =IF(ROW()<=15,"",SUM([1]Daily_Input!#REF!)) | T12: =IF(ROW()<=4,"",AVERAGE(INDEX(Daily_Input!$F:$F,ROW()-2):INDEX(Daily_Input!$F:$F,ROW()))) -> 20098.615 | U12: =IF(ROW()<=2+0,"",INDEX(Daily_Input!$G:$G,ROW()-1)) -> 15019.2 | V12: =IF(ROW()<=2+0,"",INDEX(Daily_Input!$H:$H,ROW()-1)) -> 6141.422 | W12: =IF(ROW()<=2+1,"",INDEX(Daily_Input!$G:$G,ROW()-2)) -> 15019.2 | X12: =IF(ROW()<=2+1,"",INDEX(Daily_Input!$H:$H,ROW()-2)) -> 17774.142 | Y12: =IF(ROW()<=2+2,"",INDEX(Daily_Input!$G:$G,ROW()-3)) -> 15019.2 | Z12: =IF(ROW()<=2+2,"",INDEX(Daily_Input!$H:$H,ROW()-3)) -> 22564.119 | AA12: =Daily_Input!N12 -> 20.48 | AB12: =Daily_Input!O12 -> 22.463 | AC12: =Daily_Input!P12 -> 18.722 | AD12: =IF(A12="","",SUM(AA12:AC12)) -> 61.665 | AE12: =IF(A12="","",MAX(AA12:AC12)) -> 22.463 | AF12: =IF(A12="","",IFERROR(INDEX(Daily_Input!$F:$F,ROW()+1),"")) -> 20534.223 | AG12: =IF(A12="","",IFERROR(INDEX(Daily_Input!$F:$F,ROW()+2),"")) -> 62384.338 | AH12: =IF(A12="","",IFERROR(INDEX(Daily_Input!$F:$F,ROW()+3),"")) -> 48379.885
A13: =Daily_Input!A13 -> 45850 | B13: =Daily_Input!F13 -> 20534.223 | C13: =Daily_Input!D13 -> 489.531 | D13: =Daily_Input!E13 -> 1622456.8 | E13: {=IF(ROW()=2,"",INDEX(Daily_Input!$E:$E,ROW())-INDEX(Daily_Input!$E:$E,ROW()-1))} -> -3006.9861 | F13: =IFERROR(Daily_Input!E13/Config!$B$4,"") -> 0.99815007 | G13: =Daily_Input!I13 -> 5.2 | H13: =IF(A13="","",IF(ROW()=2,G13,Config!$B$5*H12+G13)) -> 49.524913 | I13: =IF(A13="","",A13-DATE(YEAR(A13),1,0)) -> 193 | J13: =IF(I13="","",SIN(2*PI()*I13/Config!$B$6)) -> -0.17976659 | K13: =IF(I13="","",COS(2*PI()*I13/Config!$B$6)) -> -0.98370929 | L13: =IF(ROW()<=2+0,"",INDEX(Daily_Input!$F:$F,ROW()-1)) -> 9699.6258 | M13: =IF(ROW()<=2+1,"",INDEX(Daily_Input!$F:$F,ROW()-2)) -> 16680.986 | N13: =IF(ROW()<=2+2,"",INDEX(Daily_Input!$F:$F,ROW()-3)) -> 33915.235 | O13: =IF(ROW()<=2+6,"",INDEX(Daily_Input!$F:$F,ROW()-7)) -> 22689.828 | P13: =IF(ROW()<=2+13,"",INDEX([1]Daily_Input!$F:$F,ROW()-14)) | Q13: =IF(ROW()<=4,"",SUM(INDEX(Daily_Input!$I:$I,ROW()-2):INDEX(Daily_Input!$I:$I,ROW()))) -> 15.2 | R13: =IF(ROW()<=8,"",SUM(INDEX(Daily_Input!$I:$I,ROW()-6):INDEX(Daily_Input!$I:$I,ROW()))) -> 32.4 | S13: =IF(ROW()<=15,"",SUM([1]Daily_Input!#REF!)) | T13: =IF(ROW()<=4,"",AVERAGE(INDEX(Daily_Input!$F:$F,ROW()-2):INDEX(Daily_Input!$F:$F,ROW()))) -> 15638.278 | U13: =IF(ROW()<=2+0,"",INDEX(Daily_Input!$G:$G,ROW()-1)) -> 15019.2 | V13: =IF(ROW()<=2+0,"",INDEX(Daily_Input!$H:$H,ROW()-1)) -> 0 | W13: =IF(ROW()<=2+1,"",INDEX(Daily_Input!$G:$G,ROW()-2)) -> 15019.2 | X13: =IF(ROW()<=2+1,"",INDEX(Daily_Input!$H:$H,ROW()-2)) -> 6141.422 | Y13: =IF(ROW()<=2+2,"",INDEX(Daily_Input!$G:$G,ROW()-3)) -> 15019.2 | Z13: =IF(ROW()<=2+2,"",INDEX(Daily_Input!$H:$H,ROW()-3)) -> 17774.142 | AA13: =Daily_Input!N13 -> 22.463 | AB13: =Daily_Input!O13 -> 18.722 | AC13: =Daily_Input!P13 -> 18.886 | AD13: =IF(A13="","",SUM(AA13:AC13)) -> 60.071 | AE13: =IF(A13="","",MAX(AA13:AC13)) -> 22.463 | AF13: =IF(A13="","",IFERROR(INDEX(Daily_Input!$F:$F,ROW()+1),"")) -> 62384.338 | AG13: =IF(A13="","",IFERROR(INDEX(Daily_Input!$F:$F,ROW()+2),"")) -> 48379.885 | AH13: =IF(A13="","",IFERROR(INDEX(Daily_Input!$F:$F,ROW()+3),"")) -> 38218.92
A14: =Daily_Input!A14 -> 45851 | B14: =Daily_Input!F14 -> 62384.338 | C14: =Daily_Input!D14 -> 489.589 | D14: =Daily_Input!E14 -> 1637507.2 | E14: {=IF(ROW()=2,"",INDEX(Daily_Input!$E:$E,ROW())-INDEX(Daily_Input!$E:$E,ROW()-1))} -> 15050.447 | F14: =IFERROR(Daily_Input!E14/Config!$B$4,"") -> 1.0074092 | G14: =Daily_Input!I14 -> 31.6 | H14: =IF(A14="","",IF(ROW()=2,G14,Config!$B$5*H13+G14)) -> 78.648667 | I14: =IF(A14="","",A14-DATE(YEAR(A14),1,0)) -> 194 | J14: =IF(I14="","",SIN(2*PI()*I14/Config!$B$6)) -> -0.19667289 | K14: =IF(I14="","",COS(2*PI()*I14/Config!$B$6)) -> -0.98046916 | L14: =IF(ROW()<=2+0,"",INDEX(Daily_Input!$F:$F,ROW()-1)) -> 20534.223 | M14: =IF(ROW()<=2+1,"",INDEX(Daily_Input!$F:$F,ROW()-2)) -> 9699.6258 | N14: =IF(ROW()<=2+2,"",INDEX(Daily_Input!$F:$F,ROW()-3)) -> 16680.986 | O14: =IF(ROW()<=2+6,"",INDEX(Daily_Input!$F:$F,ROW()-7)) -> 41715.189 | P14: =IF(ROW()<=2+13,"",INDEX([1]Daily_Input!$F:$F,ROW()-14)) | Q14: =IF(ROW()<=4,"",SUM(INDEX(Daily_Input!$I:$I,ROW()-2):INDEX(Daily_Input!$I:$I,ROW()))) -> 38.2 | R14: =IF(ROW()<=8,"",SUM(INDEX(Daily_Input!$I:$I,ROW()-6):INDEX(Daily_Input!$I:$I,ROW()))) -> 46.8 | S14: =IF(ROW()<=15,"",SUM([1]Daily_Input!#REF!)) | T14: =IF(ROW()<=4,"",AVERAGE(INDEX(Daily_Input!$F:$F,ROW()-2):INDEX(Daily_Input!$F:$F,ROW()))) -> 30872.729 | U14: =IF(ROW()<=2+0,"",INDEX(Daily_Input!$G:$G,ROW()-1)) -> 15019.2 | V14: =IF(ROW()<=2+0,"",INDEX(Daily_Input!$H:$H,ROW()-1)) -> 8965.6721 | W14: =IF(ROW()<=2+1,"",INDEX(Daily_Input!$G:$G,ROW()-2)) -> 15019.2 | X14: =IF(ROW()<=2+1,"",INDEX(Daily_Input!$H:$H,ROW()-2)) -> 0 | Y14: =IF(ROW()<=2+2,"",INDEX(Daily_Input!$G:$G,ROW()-3)) -> 15019.2 | Z14: =IF(ROW()<=2+2,"",INDEX(Daily_Input!$H:$H,ROW()-3)) -> 6141.422 | AA14: =Daily_Input!N14 -> 18.722 | AB14: =Daily_Input!O14 -> 18.886 | AC14: =Daily_Input!P14 -> 8.722 | AD14: =IF(A14="","",SUM(AA14:AC14)) -> 46.33 | AE14: =IF(A14="","",MAX(AA14:AC14)) -> 18.886 | AF14: =IF(A14="","",IFERROR(INDEX(Daily_Input!$F:$F,ROW()+1),"")) -> 48379.885 | AG14: =IF(A14="","",IFERROR(INDEX(Daily_Input!$F:$F,ROW()+2),"")) -> 38218.92 | AH14: =IF(A14="","",IFERROR(INDEX(Daily_Input!$F:$F,ROW()+3),"")) -> 783908.45
A15: =Daily_Input!A15 -> 45852 | B15: =Daily_Input!F15 -> 48379.885 | C15: =Daily_Input!D15 -> 489.583 | D15: =Daily_Input!E15 -> 1637507.2 | E15: {=IF(ROW()=2,"",INDEX(Daily_Input!$E:$E,ROW())-INDEX(Daily_Input!$E:$E,ROW()-1))} -> 0 | F15: =IFERROR(Daily_Input!E15/Config!$B$4,"") -> 1.0074092 | G15: =Daily_Input!I15 -> 0 | H15: =IF(A15="","",IF(ROW()=2,G15,Config!$B$5*H14+G15)) -> 74.716234 | I15: =IF(A15="","",A15-DATE(YEAR(A15),1,0)) -> 195 | J15: =IF(I15="","",SIN(2*PI()*I15/Config!$B$6)) -> -0.21352092 | K15: =IF(I15="","",COS(2*PI()*I15/Config!$B$6)) -> -0.97693849 | L15: =IF(ROW()<=2+0,"",INDEX(Daily_Input!$F:$F,ROW()-1)) -> 62384.338 | M15: =IF(ROW()<=2+1,"",INDEX(Daily_Input!$F:$F,ROW()-2)) -> 20534.223 | N15: =IF(ROW()<=2+2,"",INDEX(Daily_Input!$F:$F,ROW()-3)) -> 9699.6258 | O15: =IF(ROW()<=2+6,"",INDEX(Daily_Input!$F:$F,ROW()-7)) -> 41682.058 | P15: =IF(ROW()<=2+13,"",INDEX([1]Daily_Input!$F:$F,ROW()-14)) | Q15: =IF(ROW()<=4,"",SUM(INDEX(Daily_Input!$I:$I,ROW()-2):INDEX(Daily_Input!$I:$I,ROW()))) -> 36.8 | R15: =IF(ROW()<=8,"",SUM(INDEX(Daily_Input!$I:$I,ROW()-6):INDEX(Daily_Input!$I:$I,ROW()))) -> 46.8 | S15: =IF(ROW()<=15,"",SUM([1]Daily_Input!#REF!)) | T15: =IF(ROW()<=4,"",AVERAGE(INDEX(Daily_Input!$F:$F,ROW()-2):INDEX(Daily_Input!$F:$F,ROW()))) -> 43766.149 | U15: =IF(ROW()<=2+0,"",INDEX(Daily_Input!$G:$G,ROW()-1)) -> 15019.2 | V15: =IF(ROW()<=2+0,"",INDEX(Daily_Input!$H:$H,ROW()-1)) -> 40716.29 | W15: =IF(ROW()<=2+1,"",INDEX(Daily_Input!$G:$G,ROW()-2)) -> 15019.2 | X15: =IF(ROW()<=2+1,"",INDEX(Daily_Input!$H:$H,ROW()-2)) -> 8965.6721 | Y15: =IF(ROW()<=2+2,"",INDEX(Daily_Input!$G:$G,ROW()-3)) -> 15019.2 | Z15: =IF(ROW()<=2+2,"",INDEX(Daily_Input!$H:$H,ROW()-3)) -> 0 | AA15: =Daily_Input!N15 -> 18.886 | AB15: =Daily_Input!O15 -> 8.722 | AC15: =Daily_Input!P15 -> 11.64 | AD15: =IF(A15="","",SUM(AA15:AC15)) -> 39.248 | AE15: =IF(A15="","",MAX(AA15:AC15)) -> 18.886 | AF15: =IF(A15="","",IFERROR(INDEX(Daily_Input!$F:$F,ROW()+1),"")) -> 38218.92 | AG15: =IF(A15="","",IFERROR(INDEX(Daily_Input!$F:$F,ROW()+2),"")) -> 783908.45 | AH15: =IF(A15="","",IFERROR(INDEX(Daily_Input!$F:$F,ROW()+3),"")) -> 421045.59
A16: =Daily_Input!A16 -> 45853 | B16: =Daily_Input!F16 -> 38218.92 | C16: =Daily_Input!D16 -> 489.57 | D16: =Daily_Input!E16 -> 1634494 | E16: {=IF(ROW()=2,"",INDEX(Daily_Input!$E:$E,ROW())-INDEX(Daily_Input!$E:$E,ROW()-1))} -> -3013.2032 | F16: =IFERROR(Daily_Input!E16/Config!$B$4,"") -> 1.0055555 | G16: =Daily_Input!I16 -> 0 | H16: =IF(A16="","",IF(ROW()=2,G16,Config!$B$5*H15+G16)) -> 70.980422 | I16: =IF(A16="","",A16-DATE(YEAR(A16),1,0)) -> 196 | J16: =IF(I16="","",SIN(2*PI()*I16/Config!$B$6)) -> -0.23030567 | K16: =IF(I16="","",COS(2*PI()*I16/Config!$B$6)) -> -0.97311834 | L16: =IF(ROW()<=2+0,"",INDEX(Daily_Input!$F:$F,ROW()-1)) -> 48379.885 | M16: =IF(ROW()<=2+1,"",INDEX(Daily_Input!$F:$F,ROW()-2)) -> 62384.338 | N16: =IF(ROW()<=2+2,"",INDEX(Daily_Input!$F:$F,ROW()-3)) -> 20534.223 | O16: =IF(ROW()<=2+6,"",INDEX(Daily_Input!$F:$F,ROW()-7)) -> 38705.212 | P16: =IF(ROW()<=2+13,"",INDEX(Daily_Input!$F:$F,ROW()-14)) -> 16137.621 | Q16: =IF(ROW()<=4,"",SUM(INDEX(Daily_Input!$I:$I,ROW()-2):INDEX(Daily_Input!$I:$I,ROW()))) -> 31.6 | R16: =IF(ROW()<=8,"",SUM(INDEX(Daily_Input!$I:$I,ROW()-6):INDEX(Daily_Input!$I:$I,ROW()))) -> 46.8 | S16: =IF(ROW()<=15,"",SUM(INDEX(Daily_Input!$I:$I,ROW()-13):INDEX(Daily_Input!$I:$I,ROW()))) -> 98.4 | T16: =IF(ROW()<=4,"",AVERAGE(INDEX(Daily_Input!$F:$F,ROW()-2):INDEX(Daily_Input!$F:$F,ROW()))) -> 49661.047 | U16: =IF(ROW()<=2+0,"",INDEX(Daily_Input!$G:$G,ROW()-1)) -> 15019.2 | V16: =IF(ROW()<=2+0,"",INDEX(Daily_Input!$H:$H,ROW()-1)) -> 32238.208 | W16: =IF(ROW()<=2+1,"",INDEX(Daily_Input!$G:$G,ROW()-2)) -> 15019.2 | X16: =IF(ROW()<=2+1,"",INDEX(Daily_Input!$H:$H,ROW()-2)) -> 40716.29 | Y16: =IF(ROW()<=2+2,"",INDEX(Daily_Input!$G:$G,ROW()-3)) -> 15019.2 | Z16: =IF(ROW()<=2+2,"",INDEX(Daily_Input!$H:$H,ROW()-3)) -> 8965.6721 | AA16: =Daily_Input!N16 -> 8.722 | AB16: =Daily_Input!O16 -> 11.64 | AC16: =Daily_Input!P16 -> 14.796 | AD16: =IF(A16="","",SUM(AA16:AC16)) -> 35.158 | AE16: =IF(A16="","",MAX(AA16:AC16)) -> 14.796 | AF16: =IF(A16="","",IFERROR(INDEX(Daily_Input!$F:$F,ROW()+1),"")) -> 783908.45 | AG16: =IF(A16="","",IFERROR(INDEX(Daily_Input!$F:$F,ROW()+2),"")) -> 421045.59 | AH16: =IF(A16="","",IFERROR(INDEX(Daily_Input!$F:$F,ROW()+3),"")) -> 247151.6
A17: =Daily_Input!A17 -> 45854 | B17: =Daily_Input!F17 -> 783908.45 | C17: =Daily_Input!D17 -> 489.853 | D17: =Daily_Input!E17 -> 1719668.7 | E17: {=IF(ROW()=2,"",INDEX(Daily_Input!$E:$E,ROW())-INDEX(Daily_Input!$E:$E,ROW()-1))} -> 85174.686 | F17: =IFERROR(Daily_Input!E17/Config!$B$4,"") -> 1.0579557 | G17: =Daily_Input!I17 -> 78.8 | H17: =IF(A17="","",IF(ROW()=2,G17,Config!$B$5*H16+G17)) -> 146.2314 | I17: =IF(A17="","",A17-DATE(YEAR(A17),1,0)) -> 197 | J17: =IF(I17="","",SIN(2*PI()*I17/Config!$B$6)) -> -0.24702218 | K17: =IF(I17="","",COS(2*PI()*I17/Config!$B$6)) -> -0.96900983 | L17: =IF(ROW()<=2+0,"",INDEX(Daily_Input!$F:$F,ROW()-1)) -> 38218.92 | M17: =IF(ROW()<=2+1,"",INDEX(Daily_Input!$F:$F,ROW()-2)) -> 48379.885 | N17: =IF(ROW()<=2+2,"",INDEX(Daily_Input!$F:$F,ROW()-3)) -> 62384.338 | O17: =IF(ROW()<=2+6,"",INDEX(Daily_Input!$F:$F,ROW()-7)) -> 33915.235 | P17: =IF(ROW()<=2+13,"",INDEX(Daily_Input!$F:$F,ROW()-14)) -> 18000.43 | Q17: =IF(ROW()<=4,"",SUM(INDEX(Daily_Input!$I:$I,ROW()-2):INDEX(Daily_Input!$I:$I,ROW()))) -> 78.8 | R17: =IF(ROW()<=8,"",SUM(INDEX(Daily_Input!$I:$I,ROW()-6):INDEX(Daily_Input!$I:$I,ROW()))) -> 125.6 | S17: =IF(ROW()<=15,"",SUM(INDEX(Daily_Input!$I:$I,ROW()-13):INDEX(Daily_Input!$I:$I,ROW()))) -> 173.4 | T17: =IF(ROW()<=4,"",AVERAGE(INDEX(Daily_Input!$F:$F,ROW()-2):INDEX(Daily_Input!$F:$F,ROW()))) -> 290169.08 | U17: =IF(ROW()<=2+0,"",INDEX(Daily_Input!$G:$G,ROW()-1)) -> 15019.2 | V17: =IF(ROW()<=2+0,"",INDEX(Daily_Input!$H:$H,ROW()-1)) -> 25091.03 | W17: =IF(ROW()<=2+1,"",INDEX(Daily_Input!$G:$G,ROW()-2)) -> 15019.2 | X17: =IF(ROW()<=2+1,"",INDEX(Daily_Input!$H:$H,ROW()-2)) -> 32238.208 | Y17: =IF(ROW()<=2+2,"",INDEX(Daily_Input!$G:$G,ROW()-3)) -> 15019.2 | Z17: =IF(ROW()<=2+2,"",INDEX(Daily_Input!$H:$H,ROW()-3)) -> 40716.29 | AA17: =Daily_Input!N17 -> 11.64 | AB17: =Daily_Input!O17 -> 14.796 | AC17: =Daily_Input!P17 -> 4.428 | AD17: =IF(A17="","",SUM(AA17:AC17)) -> 30.864 | AE17: =IF(A17="","",MAX(AA17:AC17)) -> 14.796 | AF17: =IF(A17="","",IFERROR(INDEX(Daily_Input!$F:$F,ROW()+1),"")) -> 421045.59 | AG17: =IF(A17="","",IFERROR(INDEX(Daily_Input!$F:$F,ROW()+2),"")) -> 247151.6 | AH17: =IF(A17="","",IFERROR(INDEX(Daily_Input!$F:$F,ROW()+3),"")) -> 142706.72
A18: =Daily_Input!A18 -> 45855 | B18: =Daily_Input!F18 -> 421045.59 | C18: =Daily_Input!D18 -> 489.763 | D18: =Daily_Input!E18 -> 1692113.7 | E18: {=IF(ROW()=2,"",INDEX(Daily_Input!$E:$E,ROW())-INDEX(Daily_Input!$E:$E,ROW()-1))} -> -27555.041 | F18: =IFERROR(Daily_Input!E18/Config!$B$4,"") -> 1.0410036 | G18: =Daily_Input!I18 -> 4.2 | H18: =IF(A18="","",IF(ROW()=2,G18,Config!$B$5*H17+G18)) -> 143.11983 | I18: =IF(A18="","",A18-DATE(YEAR(A18),1,0)) -> 198 | J18: =IF(I18="","",SIN(2*PI()*I18/Config!$B$6)) -> -0.26366549 | K18: =IF(I18="","",COS(2*PI()*I18/Config!$B$6)) -> -0.96461418 | L18: =IF(ROW()<=2+0,"",INDEX(Daily_Input!$F:$F,ROW()-1)) -> 783908.45 | M18: =IF(ROW()<=2+1,"",INDEX(Daily_Input!$F:$F,ROW()-2)) -> 38218.92 | N18: =IF(ROW()<=2+2,"",INDEX(Daily_Input!$F:$F,ROW()-3)) -> 48379.885 | O18: =IF(ROW()<=2+6,"",INDEX(Daily_Input!$F:$F,ROW()-7)) -> 16680.986 | P18: =IF(ROW()<=2+13,"",INDEX(Daily_Input!$F:$F,ROW()-14)) -> 16551.136 | Q18: =IF(ROW()<=4,"",SUM(INDEX(Daily_Input!$I:$I,ROW()-2):INDEX(Daily_Input!$I:$I,ROW()))) -> 83 | R18: =IF(ROW()<=8,"",SUM(INDEX(Daily_Input!$I:$I,ROW()-6):INDEX(Daily_Input!$I:$I,ROW()))) -> 121.2 | S18: =IF(ROW()<=15,"",SUM(INDEX(Daily_Input!$I:$I,ROW()-13):INDEX(Daily_Input!$I:$I,ROW()))) -> 177.6 | T18: =IF(ROW()<=4,"",AVERAGE(INDEX(Daily_Input!$F:$F,ROW()-2):INDEX(Daily_Input!$F:$F,ROW()))) -> 414390.99 | U18: =IF(ROW()<=2+0,"",INDEX(Daily_Input!$G:$G,ROW()-1)) -> 15019.2 | V18: =IF(ROW()<=2+0,"",INDEX(Daily_Input!$H:$H,ROW()-1)) -> 706792.16 | W18: =IF(ROW()<=2+1,"",INDEX(Daily_Input!$G:$G,ROW()-2)) -> 15019.2 | X18: =IF(ROW()<=2+1,"",INDEX(Daily_Input!$H:$H,ROW()-2)) -> 25091.03 | Y18: =IF(ROW()<=2+2,"",INDEX(Daily_Input!$G:$G,ROW()-3)) -> 15019.2 | Z18: =IF(ROW()<=2+2,"",INDEX(Daily_Input!$H:$H,ROW()-3)) -> 32238.208 | AA18: =Daily_Input!N18 -> 14.796 | AB18: =Daily_Input!O18 -> 4.428 | AC18: =Daily_Input!P18 -> 6.208 | AD18: =IF(A18="","",SUM(AA18:AC18)) -> 25.432 | AE18: =IF(A18="","",MAX(AA18:AC18)) -> 14.796 | AF18: =IF(A18="","",IFERROR(INDEX(Daily_Input!$F:$F,ROW()+1),"")) -> 247151.6 | AG18: =IF(A18="","",IFERROR(INDEX(Daily_Input!$F:$F,ROW()+2),"")) -> 142706.72 | AH18: =IF(A18="","",IFERROR(INDEX(Daily_Input!$F:$F,ROW()+3),"")) -> 99633.962
A19: =Daily_Input!A19 -> 45856 | B19: =Daily_Input!F19 -> 247151.6 | C19: =Daily_Input!D19 -> 489.698 | D19: =Daily_Input!E19 -> 1670813.5 | E19: {=IF(ROW()=2,"",INDEX(Daily_Input!$E:$E,ROW())-INDEX(Daily_Input!$E:$E,ROW()-1))} -> -21300.179 | F19: =IFERROR(Daily_Input!E19/Config!$B$4,"") -> 1.0278996 | G19: =Daily_Input!I19 -> 4.2 | H19: =IF(A19="","",IF(ROW()=2,G19,Config!$B$5*H18+G19)) -> 140.16384 | I19: =IF(A19="","",A19-DATE(YEAR(A19),1,0)) -> 199 | J19: =IF(I19="","",SIN(2*PI()*I19/Config!$B$6)) -> -0.28023068 | K19: =IF(I19="","",COS(2*PI()*I19/Config!$B$6)) -> -0.95993269 | L19: =IF(ROW()<=2+0,"",INDEX(Daily_Input!$F:$F,ROW()-1)) -> 421045.59 | M19: =IF(ROW()<=2+1,"",INDEX(Daily_Input!$F:$F,ROW()-2)) -> 783908.45 | N19: =IF(ROW()<=2+2,"",INDEX(Daily_Input!$F:$F,ROW()-3)) -> 38218.92 | O19: =IF(ROW()<=2+6,"",INDEX(Daily_Input!$F:$F,ROW()-7)) -> 9699.6258 | P19: =IF(ROW()<=2+13,"",INDEX(Daily_Input!$F:$F,ROW()-14)) -> 21950.322 | Q19: =IF(ROW()<=4,"",SUM(INDEX(Daily_Input!$I:$I,ROW()-2):INDEX(Daily_Input!$I:$I,ROW()))) -> 87.2 | R19: =IF(ROW()<=8,"",SUM(INDEX(Daily_Input!$I:$I,ROW()-6):INDEX(Daily_Input!$I:$I,ROW()))) -> 124 | S19: =IF(ROW()<=15,"",SUM(INDEX(Daily_Input!$I:$I,ROW()-13):INDEX(Daily_Input!$I:$I,ROW()))) -> 151.6 | T19: =IF(ROW()<=4,"",AVERAGE(INDEX(Daily_Input!$F:$F,ROW()-2):INDEX(Daily_Input!$F:$F,ROW()))) -> 484035.22 | U19: =IF(ROW()<=2+0,"",INDEX(Daily_Input!$G:$G,ROW()-1)) -> 15019.2 | V19: =IF(ROW()<=2+0,"",INDEX(Daily_Input!$H:$H,ROW()-1)) -> 433726.35 | W19: =IF(ROW()<=2+1,"",INDEX(Daily_Input!$G:$G,ROW()-2)) -> 15019.2 | X19: =IF(ROW()<=2+1,"",INDEX(Daily_Input!$H:$H,ROW()-2)) -> 706792.16 | Y19: =IF(ROW()<=2+2,"",INDEX(Daily_Input!$G:$G,ROW()-3)) -> 15019.2 | Z19: =IF(ROW()<=2+2,"",INDEX(Daily_Input!$H:$H,ROW()-3)) -> 25091.03 | AA19: =Daily_Input!N19 -> 4.428 | AB19: =Daily_Input!O19 -> 6.208 | AC19: =Daily_Input!P19 -> 33.034 | AD19: =IF(A19="","",SUM(AA19:AC19)) -> 43.67 | AE19: =IF(A19="","",MAX(AA19:AC19)) -> 33.034 | AF19: =IF(A19="","",IFERROR(INDEX(Daily_Input!$F:$F,ROW()+1),"")) -> 142706.72 | AG19: =IF(A19="","",IFERROR(INDEX(Daily_Input!$F:$F,ROW()+2),"")) -> 99633.962 | AH19: =IF(A19="","",IFERROR(INDEX(Daily_Input!$F:$F,ROW()+3),"")) -> 81725.689
A20: =Daily_Input!A20 -> 45857 | B20: =Daily_Input!F20 -> 142706.72 | C20: =Daily_Input!D20 -> 489.648 | D20: =Daily_Input!E20 -> 1655645.2 | E20: {=IF(ROW()=2,"",INDEX(Daily_Input!$E:$E,ROW())-INDEX(Daily_Input!$E:$E,ROW()-1))} -> -15168.321 | F20: =IFERROR(Daily_Input!E20/Config!$B$4,"") -> 1.0185679 | G20: =Daily_Input!I20 -> 0 | H20: =IF(A20="","",IF(ROW()=2,G20,Config!$B$5*H19+G20)) -> 133.15565 | I20: =IF(A20="","",A20-DATE(YEAR(A20),1,0)) -> 200 | J20: =IF(I20="","",SIN(2*PI()*I20/Config!$B$6)) -> -0.29671282 | K20: =IF(I20="","",COS(2*PI()*I20/Config!$B$6)) -> -0.95496675 | L20: =IF(ROW()<=2+0,"",INDEX(Daily_Input!$F:$F,ROW()-1)) -> 247151.6 | M20: =IF(ROW()<=2+1,"",INDEX(Daily_Input!$F:$F,ROW()-2)) -> 421045.59 | N20: =IF(ROW()<=2+2,"",INDEX(Daily_Input!$F:$F,ROW()-3)) -> 783908.45 | O20: =IF(ROW()<=2+6,"",INDEX(Daily_Input!$F:$F,ROW()-7)) -> 20534.223 | P20: =IF(ROW()<=2+13,"",INDEX(Daily_Input!$F:$F,ROW()-14)) -> 22689.828 | Q20: =IF(ROW()<=4,"",SUM(INDEX(Daily_Input!$I:$I,ROW()-2):INDEX(Daily_Input!$I:$I,ROW()))) -> 8.4 | R20: =IF(ROW()<=8,"",SUM(INDEX(Daily_Input!$I:$I,ROW()-6):INDEX(Daily_Input!$I:$I,ROW()))) -> 118.8 | S20: =IF(ROW()<=15,"",SUM(INDEX(Daily_Input!$I:$I,ROW()-13):INDEX(Daily_Input!$I:$I,ROW()))) -> 151.2 | T20: =IF(ROW()<=4,"",AVERAGE(INDEX(Daily_Input!$F:$F,ROW()-2):INDEX(Daily_Input!$F:$F,ROW()))) -> 270301.31 | U20: =IF(ROW()<=2+0,"",INDEX(Daily_Input!$G:$G,ROW()-1)) -> 15019.2 | V20: =IF(ROW()<=2+0,"",INDEX(Daily_Input!$H:$H,ROW()-1)) -> 253577.02 | W20: =IF(ROW()<=2+1,"",INDEX(Daily_Input!$G:$G,ROW()-2)) -> 15019.2 | X20: =IF(ROW()<=2+1,"",INDEX(Daily_Input!$H:$H,ROW()-2)) -> 433726.35 | Y20: =IF(ROW()<=2+2,"",INDEX(Daily_Input!$G:$G,ROW()-3)) -> 15019.2 | Z20: =IF(ROW()<=2+2,"",INDEX(Daily_Input!$H:$H,ROW()-3)) -> 706792.16 | AA20: =Daily_Input!N20 -> 6.208 | AB20: =Daily_Input!O20 -> 33.034 | AC20: =Daily_Input!P20 -> 3.545 | AD20: =IF(A20="","",SUM(AA20:AC20)) -> 42.787 | AE20: =IF(A20="","",MAX(AA20:AC20)) -> 33.034 | AF20: =IF(A20="","",IFERROR(INDEX(Daily_Input!$F:$F,ROW()+1),"")) -> 99633.962 | AG20: =IF(A20="","",IFERROR(INDEX(Daily_Input!$F:$F,ROW()+2),"")) -> 81725.689 | AH20: =IF(A20="","",IFERROR(INDEX(Daily_Input!$F:$F,ROW()+3),"")) -> 54196.435
A21: =Daily_Input!A21 -> 45858 | B21: =Daily_Input!F21 -> 99633.962 | C21: =Daily_Input!D21 -> 489.608 | D21: =Daily_Input!E21 -> 1643538.2 | E21: {=IF(ROW()=2,"",INDEX(Daily_Input!$E:$E,ROW())-INDEX(Daily_Input!$E:$E,ROW()-1))} -> -12106.945 | F21: =IFERROR(Daily_Input!E21/Config!$B$4,"") -> 1.0111196 | G21: =Daily_Input!I21 -> 0 | H21: =IF(A21="","",IF(ROW()=2,G21,Config!$B$5*H20+G21)) -> 126.49787 | I21: =IF(A21="","",A21-DATE(YEAR(A21),1,0)) -> 201 | J21: =IF(I21="","",SIN(2*PI()*I21/Config!$B$6)) -> -0.31310704 | K21: =IF(I21="","",COS(2*PI()*I21/Config!$B$6)) -> -0.94971784 | L21: =IF(ROW()<=2+0,"",INDEX(Daily_Input!$F:$F,ROW()-1)) -> 142706.72 | M21: =IF(ROW()<=2+1,"",INDEX(Daily_Input!$F:$F,ROW()-2)) -> 247151.6 | N21: =IF(ROW()<=2+2,"",INDEX(Daily_Input!$F:$F,ROW()-3)) -> 421045.59 | O21: =IF(ROW()<=2+6,"",INDEX(Daily_Input!$F:$F,ROW()-7)) -> 62384.338 | P21: =IF(ROW()<=2+13,"",INDEX(Daily_Input!$F:$F,ROW()-14)) -> 41715.189 | Q21: =IF(ROW()<=4,"",SUM(INDEX(Daily_Input!$I:$I,ROW()-2):INDEX(Daily_Input!$I:$I,ROW()))) -> 4.2 | R21: =IF(ROW()<=8,"",SUM(INDEX(Daily_Input!$I:$I,ROW()-6):INDEX(Daily_Input!$I:$I,ROW()))) -> 87.2 | S21: =IF(ROW()<=15,"",SUM(INDEX(Daily_Input!$I:$I,ROW()-13):INDEX(Daily_Input!$I:$I,ROW()))) -> 134 | T21: =IF(ROW()<=4,"",AVERAGE(INDEX(Daily_Input!$F:$F,ROW()-2):INDEX(Daily_Input!$F:$F,ROW()))) -> 163164.09 | U21: =IF(ROW()<=2+0,"",INDEX(Daily_Input!$G:$G,ROW()-1)) -> 15019.2 | V21: =IF(ROW()<=2+0,"",INDEX(Daily_Input!$H:$H,ROW()-1)) -> 141727.38 | W21: =IF(ROW()<=2+1,"",INDEX(Daily_Input!$G:$G,ROW()-2)) -> 15019.2 | X21: =IF(ROW()<=2+1,"",INDEX(Daily_Input!$H:$H,ROW()-2)) -> 253577.02 | Y21: =IF(ROW()<=2+2,"",INDEX(Daily_Input!$G:$G,ROW()-3)) -> 15019.2 | Z21: =IF(ROW()<=2+2,"",INDEX(Daily_Input!$H:$H,ROW()-3)) -> 433726.35 | AA21: =Daily_Input!N21 -> 33.034 | AB21: =Daily_Input!O21 -> 3.545 | AC21: =Daily_Input!P21 -> 12.694 | AD21: =IF(A21="","",SUM(AA21:AC21)) -> 49.273 | AE21: =IF(A21="","",MAX(AA21:AC21)) -> 33.034 | AF21: =IF(A21="","",IFERROR(INDEX(Daily_Input!$F:$F,ROW()+1),"")) -> 81725.689 | AG21: =IF(A21="","",IFERROR(INDEX(Daily_Input!$F:$F,ROW()+2),"")) -> 54196.435 | AH21: =IF(A21="","",IFERROR(INDEX(Daily_Input!$F:$F,ROW()+3),"")) -> 1408228.3
A22: =Daily_Input!A22 -> 45859 | B22: =Daily_Input!F22 -> 81725.689 | C22: =Daily_Input!D22 -> 489.608 | D22: =Daily_Input!E22 -> 1643538.2 | E22: {=IF(ROW()=2,"",INDEX(Daily_Input!$E:$E,ROW())-INDEX(Daily_Input!$E:$E,ROW()-1))} -> 0 | F22: =IFERROR(Daily_Input!E22/Config!$B$4,"") -> 1.0111196 | G22: =Daily_Input!I22 -> 19.8 | H22: =IF(A22="","",IF(ROW()=2,G22,Config!$B$5*H21+G22)) -> 139.97297 | I22: =IF(A22="","",A22-DATE(YEAR(A22),1,0)) -> 202 | J22: =IF(I22="","",SIN(2*PI()*I22/Config!$B$6)) -> -0.32940848 | K22: =IF(I22="","",COS(2*PI()*I22/Config!$B$6)) -> -0.94418751 | L22: =IF(ROW()<=2+0,"",INDEX(Daily_Input!$F:$F,ROW()-1)) -> 99633.962 | M22: =IF(ROW()<=2+1,"",INDEX(Daily_Input!$F:$F,ROW()-2)) -> 142706.72 | N22: =IF(ROW()<=2+2,"",INDEX(Daily_Input!$F:$F,ROW()-3)) -> 247151.6 | O22: =IF(ROW()<=2+6,"",INDEX(Daily_Input!$F:$F,ROW()-7)) -> 48379.885 | P22: =IF(ROW()<=2+13,"",INDEX(Daily_Input!$F:$F,ROW()-14)) -> 41682.058 | Q22: =IF(ROW()<=4,"",SUM(INDEX(Daily_Input!$I:$I,ROW()-2):INDEX(Daily_Input!$I:$I,ROW()))) -> 19.8 | R22: =IF(ROW()<=8,"",SUM(INDEX(Daily_Input!$I:$I,ROW()-6):INDEX(Daily_Input!$I:$I,ROW()))) -> 107 | S22: =IF(ROW()<=15,"",SUM(INDEX(Daily_Input!$I:$I,ROW()-13):INDEX(Daily_Input!$I:$I,ROW()))) -> 153.8 | T22: =IF(ROW()<=4,"",AVERAGE(INDEX(Daily_Input!$F:$F,ROW()-2):INDEX(Daily_Input!$F:$F,ROW()))) -> 108022.12 | U22: =IF(ROW()<=2+0,"",INDEX(Daily_Input!$G:$G,ROW()-1)) -> 15019.2 | V22: =IF(ROW()<=2+0,"",INDEX(Daily_Input!$H:$H,ROW()-1)) -> 95597.933 | W22: =IF(ROW()<=2+1,"",INDEX(Daily_Input!$G:$G,ROW()-2)) -> 15019.2 | X22: =IF(ROW()<=2+1,"",INDEX(Daily_Input!$H:$H,ROW()-2)) -> 141727.38 | Y22: =IF(ROW()<=2+2,"",INDEX(Daily_Input!$G:$G,ROW()-3)) -> 15019.2 | Z22: =IF(ROW()<=2+2,"",INDEX(Daily_Input!$H:$H,ROW()-3)) -> 253577.02 | AA22: =Daily_Input!N22 -> 3.545 | AB22: =Daily_Input!O22 -> 12.694 | AC22: =Daily_Input!P22 -> 6.008 | AD22: =IF(A22="","",SUM(AA22:AC22)) -> 22.247 | AE22: =IF(A22="","",MAX(AA22:AC22)) -> 12.694 | AF22: =IF(A22="","",IFERROR(INDEX(Daily_Input!$F:$F,ROW()+1),"")) -> 54196.435 | AG22: =IF(A22="","",IFERROR(INDEX(Daily_Input!$F:$F,ROW()+2),"")) -> 1408228.3 | AH22: =IF(A22="","",IFERROR(INDEX(Daily_Input!$F:$F,ROW()+3),"")) -> 1123235
A23: =Daily_Input!A23 -> 45860 | B23: =Daily_Input!F23 -> 54196.435 | C23: =Daily_Input!D23 -> 489.589 | D23: =Daily_Input!E23 -> 1637507.2 | E23: {=IF(ROW()=2,"",INDEX(Daily_Input!$E:$E,ROW())-INDEX(Daily_Input!$E:$E,ROW()-1))} -> -6030.9967 | F23: =IFERROR(Daily_Input!E23/Config!$B$4,"") -> 1.0074092 | G23: =Daily_Input!I23 -> 0 | H23: =IF(A23="","",IF(ROW()=2,G23,Config!$B$5*H22+G23)) -> 132.97432 | I23: =IF(A23="","",A23-DATE(YEAR(A23),1,0)) -> 203 | J23: =IF(I23="","",SIN(2*PI()*I23/Config!$B$6)) -> -0.34561231 | K23: =IF(I23="","",COS(2*PI()*I23/Config!$B$6)) -> -0.93837739 | L23: =IF(ROW()<=2+0,"",INDEX(Daily_Input!$F:$F,ROW()-1)) -> 81725.689 | M23: =IF(ROW()<=2+1,"",INDEX(Daily_Input!$F:$F,ROW()-2)) -> 99633.962 | N23: =IF(ROW()<=2+2,"",INDEX(Daily_Input!$F:$F,ROW()-3)) -> 142706.72 | O23: =IF(ROW()<=2+6,"",INDEX(Daily_Input!$F:$F,ROW()-7)) -> 38218.92 | P23: =IF(ROW()<=2+13,"",INDEX(Daily_Input!$F:$F,ROW()-14)) -> 38705.212 | Q23: =IF(ROW()<=4,"",SUM(INDEX(Daily_Input!$I:$I,ROW()-2):INDEX(Daily_Input!$I:$I,ROW()))) -> 19.8 | R23: =IF(ROW()<=8,"",SUM(INDEX(Daily_Input!$I:$I,ROW()-6):INDEX(Daily_Input!$I:$I,ROW()))) -> 107 | S23: =IF(ROW()<=15,"",SUM(INDEX(Daily_Input!$I:$I,ROW()-13):INDEX(Daily_Input!$I:$I,ROW()))) -> 153.8 | T23: =IF(ROW()<=4,"",AVERAGE(INDEX(Daily_Input!$F:$F,ROW()-2):INDEX(Daily_Input!$F:$F,ROW()))) -> 78518.695 | U23: =IF(ROW()<=2+0,"",INDEX(Daily_Input!$G:$G,ROW()-1)) -> 15019.2 | V23: =IF(ROW()<=2+0,"",INDEX(Daily_Input!$H:$H,ROW()-1)) -> 71557.166 | W23: =IF(ROW()<=2+1,"",INDEX(Daily_Input!$G:$G,ROW()-2)) -> 15019.2 | X23: =IF(ROW()<=2+1,"",INDEX(Daily_Input!$H:$H,ROW()-2)) -> 95597.933 | Y23: =IF(ROW()<=2+2,"",INDEX(Daily_Input!$G:$G,ROW()-3)) -> 15019.2 | Z23: =IF(ROW()<=2+2,"",INDEX(Daily_Input!$H:$H,ROW()-3)) -> 141727.38 | AA23: =Daily_Input!N23 -> 12.694 | AB23: =Daily_Input!O23 -> 6.008 | AC23: =Daily_Input!P23 -> 4.704 | AD23: =IF(A23="","",SUM(AA23:AC23)) -> 23.406 | AE23: =IF(A23="","",MAX(AA23:AC23)) -> 12.694 | AF23: =IF(A23="","",IFERROR(INDEX(Daily_Input!$F:$F,ROW()+1),"")) -> 1408228.3 | AG23: =IF(A23="","",IFERROR(INDEX(Daily_Input!$F:$F,ROW()+2),"")) -> 1123235 | AH23: =IF(A23="","",IFERROR(INDEX(Daily_Input!$F:$F,ROW()+3),"")) -> 618651.26
A24: =Daily_Input!A24 -> 45861 | B24: =Daily_Input!F24 -> 1408228.3 | C24: =Daily_Input!D24 -> 489.801 | D24: =Daily_Input!E24 -> 1704320.3 | E24: {=IF(ROW()=2,"",INDEX(Daily_Input!$E:$E,ROW())-INDEX(Daily_Input!$E:$E,ROW()-1))} -> 66813.048 | F24: =IFERROR(Daily_Input!E24/Config!$B$4,"") -> 1.0485132 | G24: =Daily_Input!I24 -> 58.6 | H24: =IF(A24="","",IF(ROW()=2,G24,Config!$B$5*H23+G24)) -> 184.92561 | I24: =IF(A24="","",A24-DATE(YEAR(A24),1,0)) -> 204 | J24: =IF(I24="","",SIN(2*PI()*I24/Config!$B$6)) -> -0.36171373 | K24: =IF(I24="","",COS(2*PI()*I24/Config!$B$6)) -> -0.93228921 | L24: =IF(ROW()<=2+0,"",INDEX(Daily_Input!$F:$F,ROW()-1)) -> 54196.435 | M24: =IF(ROW()<=2+1,"",INDEX(Daily_Input!$F:$F,ROW()-2)) -> 81725.689 | N24: =IF(ROW()<=2+2,"",INDEX(Daily_Input!$F:$F,ROW()-3)) -> 99633.962 | O24: =IF(ROW()<=2+6,"",INDEX(Daily_Input!$F:$F,ROW()-7)) -> 783908.45 | P24: =IF(ROW()<=2+13,"",INDEX(Daily_Input!$F:$F,ROW()-14)) -> 33915.235 | Q24: =IF(ROW()<=4,"",SUM(INDEX(Daily_Input!$I:$I,ROW()-2):INDEX(Daily_Input!$I:$I,ROW()))) -> 78.4 | R24: =IF(ROW()<=8,"",SUM(INDEX(Daily_Input!$I:$I,ROW()-6):INDEX(Daily_Input!$I:$I,ROW()))) -> 86.8 | S24: =IF(ROW()<=15,"",SUM(INDEX(Daily_Input!$I:$I,ROW()-13):INDEX(Daily_Input!$I:$I,ROW()))) -> 212.4 | T24: =IF(ROW()<=4,"",AVERAGE(INDEX(Daily_Input!$F:$F,ROW()-2):INDEX(Daily_Input!$F:$F,ROW()))) -> 514716.81 | U24: =IF(ROW()<=2+0,"",INDEX(Daily_Input!$G:$G,ROW()-1)) -> 15019.2 | V24: =IF(ROW()<=2+0,"",INDEX(Daily_Input!$H:$H,ROW()-1)) -> 44085.754 | W24: =IF(ROW()<=2+1,"",INDEX(Daily_Input!$G:$G,ROW()-2)) -> 15019.2 | X24: =IF(ROW()<=2+1,"",INDEX(Daily_Input!$H:$H,ROW()-2)) -> 71557.166 | Y24: =IF(ROW()<=2+2,"",INDEX(Daily_Input!$G:$G,ROW()-3)) -> 15019.2 | Z24: =IF(ROW()<=2+2,"",INDEX(Daily_Input!$H:$H,ROW()-3)) -> 95597.933 | AA24: =Daily_Input!N24 -> 6.008 | AB24: =Daily_Input!O24 -> 4.704 | AC24: =Daily_Input!P24 -> 4.006 | AD24: =IF(A24="","",SUM(AA24:AC24)) -> 14.718 | AE24: =IF(A24="","",MAX(AA24:AC24)) -> 6.008 | AF24: =IF(A24="","",IFERROR(INDEX(Daily_Input!$F:$F,ROW()+1),"")) -> 1123235 | AG24: =IF(A24="","",IFERROR(INDEX(Daily_Input!$F:$F,ROW()+2),"")) -> 618651.26 | AH24: =IF(A24="","",IFERROR(INDEX(Daily_Input!$F:$F,ROW()+3),"")) -> 482554.31
