Workbook

Sheet RES002 (Adj)
A1: date | B1: time | C1: rainfall | D1: water_level | E1: water_level (ADJ) | F1: Volume (M3) | G1: Spillway_level | H1: H (M.) | I1: C | J1: Q (m3/s) | K1: Q (m3/m) | L1: Volume (m3/h) | M1: Water release (M3/h) | O1: Inflow (M3/h)
A2: 45834.75 | B2: =MOD(A2,1) -> 0.75 | C2: 0 | D2: 489.48602 | E2: =D2-0.155 -> 489.33102 | F2: =_xlfn.XLOOKUP(D2,'Rating Curve'!$A$2:$A$500,'Rating Curve'!$D$2:$D$500,, -1) -> 1607444.6 | G2: 489.545 | H2: =IF(D2 - G2 < 0, 0, D2 - G2) -> 0 | I2: 1.82 | J2: =1.82*30*(H2^1.5) -> 0 | K2: =J2*60 -> 0 | L2: =(J2*86400)/24 -> 0 | M2: 625.8 | O2: 0 | S2: Q=CLH1.5
A3: 45834.792 | B3: =MOD(A3,1) -> 0.79166667 | C3: 0 | D3: 489.479 | E3: =D3-0.155 -> 489.324 | F3: =_xlfn.XLOOKUP(D3,'Rating Curve'!$A$2:$A$500,'Rating Curve'!$D$2:$D$500,, -1) -> 1604446.7 | G3: 489.545 | H3: =IF(D3 - G3 < 0, 0, D3 - G3) -> 0 | I3: 1.82 | J3: =1.82*30*(H3^1.5) -> 0 | K3: =J3*60 -> 0 | L3: =(J3*86400)/24 -> 0 | M3: 625.8 | O3: =IF((F3-F2)+M3+L3 < 0, 0, (F3-F2)+M3+L3) -> 0
A4: 45834.833 | B4: =MOD(A4,1) -> 0.83333333 | C4: 0 | D4: 489.479 | E4: =D4-0.155 -> 489.324 | F4: =_xlfn.XLOOKUP(D4,'Rating Curve'!$A$2:$A$500,'Rating Curve'!$D$2:$D$500,, -1) -> 1604446.7 | G4: 489.545 | H4: =IF(D4 - G4 < 0, 0, D4 - G4) -> 0 | I4: 1.82 | J4: =1.82*30*(H4^1.5) -> 0 | K4: =J4*60 -> 0 | L4: =(J4*86400)/24 -> 0 | M4: 625.8 | O4: =IF((F4-F3)+M4+L4 < 0, 0, (F4-F3)+M4+L4) -> 625.8
A5: 45834.875 | B5: =MOD(A5,1) -> 0.875 | C5: 0 | D5: 489.48602 | E5: =D5-0.155 -> 489.33102 | F5: =_xlfn.XLOOKUP(D5,'Rating Curve'!$A$2:$A$500,'Rating Curve'!$D$2:$D$500,, -1) -> 1607444.6 | G5: 489.545 | H5: =IF(D5 - G5 < 0, 0, D5 - G5) -> 0 | I5: 1.82 | J5: =1.82*30*(H5^1.5) -> 0 | K5: =J5*60 -> 0 | L5: =(J5*86400)/24 -> 0 | M5: 625.8 | O5: =IF((F5-F4)+M5+L5 < 0, 0, (F5-F4)+M5+L5) -> 3623.6745
A6: 45834.917 | B6: =MOD(A6,1) -> 0.91666667 | C6: 0 | D6: 489.479 | E6: =D6-0.155 -> 489.324 | F6: =_xlfn.XLOOKUP(D6,'Rating Curve'!$A$2:$A$500,'Rating Curve'!$D$2:$D$500,, -1) -> 1604446.7 | G6: 489.545 | H6: =IF(D6 - G6 < 0, 0, D6 - G6) -> 0 | I6: 1.82 | J6: =1.82*30*(H6^1.5) -> 0 | K6: =J6*60 -> 0 | L6: =(J6*86400)/24 -> 0 | M6: 625.8 | O6: =IF((F6-F5)+M6+L6 < 0, 0, (F6-F5)+M6+L6) -> 0
A7: 45834.958 | B7: =MOD(A7,1) -> 0.95833333 | C7: 0 | D7: 489.48602 | E7: =D7-0.155 -> 489.33102 | F7: =_xlfn.XLOOKUP(D7,'Rating Curve'!$A$2:$A$500,'Rating Curve'!$D$2:$D$500,, -1) -> 1607444.6 | G7: 489.545 | H7: =IF(D7 - G7 < 0, 0, D7 - G7) -> 0 | I7: 1.82 | J7: =1.82*30*(H7^1.5) -> 0 | K7: =J7*60 -> 0 | L7: =(J7*86400)/24 -> 0 | M7: 625.8 | O7: =IF((F7-F6)+M7+L7 < 0, 0, (F7-F6)+M7+L7) -> 3623.6745
A8: 45835 | B8: =MOD(A8,1) -> 0 | C8: 0 | D8: 489.48 | E8: =D8-0.155 -> 489.325 | F8: =_xlfn.XLOOKUP(D8,'Rating Curve'!$A$2:$A$500,'Rating Curve'!$D$2:$D$500,, -1) -> 1607444.6 | G8: 489.545 | H8: =IF(D8 - G8 < 0, 0, D8 - G8) -> 0 | I8: 1.82 | J8: =1.82*30*(H8^1.5) -> 0 | K8: =J8*60 -> 0 | L8: =(J8*86400)/24 -> 0 | M8: 625.8 | O8: =IF((F8-F7)+M8+L8 < 0, 0, (F8-F7)+M8+L8) -> 625.8
A9: 45835.042 | B9: =MOD(A9,1) -> 0.041666667 | C9: 0 | D9: 489.48 | E9: =D9-0.155 -> 489.325 | F9: =_xlfn.XLOOKUP(D9,'Rating Curve'!$A$2:$A$500,'Rating Curve'!$D$2:$D$500,, -1) -> 1607444.6 | G9: 489.545 | H9: =IF(D9 - G9 < 0, 0, D9 - G9) -> 0 | I9: 1.82 | J9: =1.82*30*(H9^1.5) -> 0 | K9: =J9*60 -> 0 | L9: =(J9*86400)/24 -> 0 | M9: 625.8 | O9: =IF((F9-F8)+M9+L9 < 0, 0, (F9-F8)+M9+L9) -> 625.8
A10: 45835.083 | B10: =MOD(A10,1) -> 0.083333333 | C10: 0 | D10: 489.479 | E10: =D10-0.155 -> 489.324 | F10: =_xlfn.XLOOKUP(D10,'Rating Curve'!$A$2:$A$500,'Rating Curve'!$D$2:$D$500,, -1) -> 1604446.7 | G10: 489.545 | H10: =IF(D10 - G10 < 0, 0, D10 - G10) -> 0 | I10: 1.82 | J10: =1.82*30*(H10^1.5) -> 0 | K10: =J10*60 -> 0 | L10: =(J10*86400)/24 -> 0 | M10: 625.8 | O10: =IF((F10-F9)+M10+L10 < 0, 0, (F10-F9)+M10+L10) -> 0
A11: 45835.125 | B11: =MOD(A11,1) -> 0.125 | C11: 0 | D11: 489.48602 | E11: =D11-0.155 -> 489.33102 | F11: =_xlfn.XLOOKUP(D11,'Rating Curve'!$A$2:$A$500,'Rating Curve'!$D$2:$D$500,, -1) -> 1607444.6 | G11: 489.545 | H11: =IF(D11 - G11 < 0, 0, D11 - G11) -> 0 | I11: 1.82 | J11: =1.82*30*(H11^1.5) -> 0 | K11: =J11*60 -> 0 | L11: =(J11*86400)/24 -> 0 | M11: 625.8 | O11: =IF((F11-F10)+M11+L11 < 0, 0, (F11-F10)+M11+L11) -> 3623.6745
A12: 45835.167 | B12: =MOD(A12,1) -> 0.16666667 | C12: 0 | D12: 489.48602 | E12: =D12-0.155 -> 489.33102 | F12: =_xlfn.XLOOKUP(D12,'Rating Curve'!$A$2:$A$500,'Rating Curve'!$D$2:$D$500,, -1) -> 1607444.6 | G12: 489.545 | H12: =IF(D12 - G12 < 0, 0, D12 - G12) -> 0 | I12: 1.82 | J12: =1.82*30*(H12^1.5) -> 0 | K12: =J12*60 -> 0 | L12: =(J12*86400)/24 -> 0 | M12: 625.8 | O12: =IF((F12-F11)+M12+L12 < 0, 0, (F12-F11)+M12+L12) -> 625.8
A13: 45835.208 | B13: =MOD(A13,1) -> 0.20833333 | C13: 0 | D13: 489.48602 | E13: =D13-0.155 -> 489.33102 | F13: =_xlfn.XLOOKUP(D13,'Rating Curve'!$A$2:$A$500,'Rating Curve'!$D$2:$D$500,, -1) -> 1607444.6 | G13: 489.545 | H13: =IF(D13 - G13 < 0, 0, D13 - G13) -> 0 | I13: 1.82 | J13: =1.82*30*(H13^1.5) -> 0 | K13: =J13*60 -> 0 | L13: =(J13*86400)/24 -> 0 | M13: 625.8 | O13: =IF((F13-F12)+M13+L13 < 0, 0, (F13-F12)+M13+L13) -> 625.8
A14: 45835.25 | B14: =MOD(A14,1) -> 0.25 | C14: 0 | D14: 489.48602 | E14: =D14-0.155 -> 489.33102 | F14: =_xlfn.XLOOKUP(D14,'Rating Curve'!$A$2:$A$500,'Rating Curve'!$D$2:$D$500,, -1) -> 1607444.6 | G14: 489.545 | H14: =IF(D14 - G14 < 0, 0, D14 - G14) -> 0 | I14: 1.82 | J14: =1.82*30*(H14^1.5) -> 0 | K14: =J14*60 -> 0 | L14: =(J14*86400)/24 -> 0 | M14: 625.8 | O14: =IF((F14-F13)+M14+L14 < 0, 0, (F14-F13)+M14+L14) -> 625.8
... A1758: 45907.917 | B1758: =MOD(A1758,1) -> 0.91666667 | C1758: 0 | D1758: 489.551 | E1758: =D1758-0.155 -> 489.396 | F1758: =_xlfn.XLOOKUP(D1758,'Rating Curve'!$A$2:$A$500,'Rating Curve'!$D$2:$D$500,, -1) -> 1628472.3 | G1758: 489.545 | H1758: =IF(D1758 - G1758 < 0, 0, D1758 - G1758) -> 0.006 | I1758: 1.82 | J1758: =1.82*30*(H1758^1.5) -> 0.025375787 | K1758: =J1758*60 -> 1.5225472 | L1758: =(J1758*86400)/24 -> 91.352833 | M1758: 625.8 | O1758: =IF((F1758-F1757)+M1758+L1758 < 0, 0, (F1758-F1757)+M1758+L1758) -> 717.15283
A1759: 45907.958 | B1759: =MOD(A1759,1) -> 0.95833333 | C1759: 0 | D1759: 489.552 | E1759: =D1759-0.155 -> 489.397 | F1759: =_xlfn.XLOOKUP(D1759,'Rating Curve'!$A$2:$A$500,'Rating Curve'!$D$2:$D$500,, -1) -> 1628472.3 | G1759: 489.545 | H1759: =IF(D1759 - G1759 < 0, 0, D1759 - G1759) -> 0.007 | I1759: 1.82 | J1759: =1.82*30*(H1759^1.5) -> 0.031977146 | L1759: =(J1759*86400)/24 -> 115.11773 | M1759: 625.8 | O1759: =IF((F1759-F1758)+M1759+L1759 < 0, 0, (F1759-F1758)+M1759+L1759) -> 740.91773
A1760: 45908 | B1760: =MOD(A1760,1) -> 0 | C1760: 0 | D1760: 489.551 | E1760: =D1760-0.155 -> 489.396 | F1760: =_xlfn.XLOOKUP(D1760,'Rating Curve'!$A$2:$A$500,'Rating Curve'!$D$2:$D$500,, -1) -> 1628472.3 | G1760: 489.545 | H1760: =IF(D1760 - G1760 < 0, 0, D1760 - G1760) -> 0.006 | I1760: 1.82 | J1760: =1.82*30*(H1760^1.5) -> 0.025375787 | L1760: =(J1760*86400)/24 -> 91.352833 | M1760: 625.8 | O1760: =IF((F1760-F1759)+M1760+L1760 < 0, 0, (F1760-F1759)+M1760+L1760) -> 717.15283
A1761: 45908.042 | B1761: =MOD(A1761,1) -> 0.041666667 | C1761: 0 | D1761: 489.552 | E1761: =D1761-0.155 -> 489.397 | F1761: =_xlfn.XLOOKUP(D1761,'Rating Curve'!$A$2:$A$500,'Rating Curve'!$D$2:$D$500,, -1) -> 1628472.3 | G1761: 489.545 | H1761: =IF(D1761 - G1761 < 0, 0, D1761 - G1761) -> 0.007 | I1761: 1.82 | J1761: =1.82*30*(H1761^1.5) -> 0.031977146 | L1761: =(J1761*86400)/24 -> 115.11773 | M1761: 625.8 | O1761: =IF((F1761-F1760)+M1761+L1761 < 0, 0, (F1761-F1760)+M1761+L1761) -> 740.91773
A1762: 45908.083 | B1762: =MOD(A1762,1) -> 0.083333333 | C1762: 0 | D1762: 489.552 | E1762: =D1762-0.155 -> 489.397 | F1762: =_xlfn.XLOOKUP(D1762,'Rating Curve'!$A$2:$A$500,'Rating Curve'!$D$2:$D$500,, -1) -> 1628472.3 | G1762: 489.545 | H1762: =IF(D1762 - G1762 < 0, 0, D1762 - G1762) -> 0.007 | I1762: 1.82 | J1762: =1.82*30*(H1762^1.5) -> 0.031977146 | L1762: =(J1762*86400)/24 -> 115.11773 | M1762: 625.8 | O1762: =IF((F1762-F1761)+M1762+L1762 < 0, 0, (F1762-F1761)+M1762+L1762) -> 740.91773
A1763: 45908.125 | B1763: =MOD(A1763,1) -> 0.125 | C1763: 0 | D1763: 489.544 | E1763: =D1763-0.155 -> 489.389 | F1763: =_xlfn.XLOOKUP(D1763,'Rating Curve'!$A$2:$A$500,'Rating Curve'!$D$2:$D$500,, -1) -> 1625463.8 | G1763: 489.545 | H1763: =IF(D1763 - G1763 < 0, 0, D1763 - G1763) -> 0 | I1763: 1.82 | J1763: =1.82*30*(H1763^1.5) -> 0 | L1763: =(J1763*86400)/24 -> 0 | M1763: 625.8 | O1763: =IF((F1763-F1762)+M1763+L1763 < 0, 0, (F1763-F1762)+M1763+L1763) -> 0
A1764: 45908.167 | B1764: =MOD(A1764,1) -> 0.16666667 | C1764: 0 | D1764: 489.544 | E1764: =D1764-0.155 -> 489.389 | F1764: =_xlfn.XLOOKUP(D1764,'Rating Curve'!$A$2:$A$500,'Rating Curve'!$D$2:$D$500,, -1) -> 1625463.8 | G1764: 489.545 | H1764: =IF(D1764 - G1764 < 0, 0, D1764 - G1764) -> 0 | I1764: 1.82 | J1764: =1.82*30*(H1764^1.5) -> 0 | L1764: =(J1764*86400)/24 -> 0 | M1764: 625.8 | O1764: =IF((F1764-F1763)+M1764+L1764 < 0, 0, (F1764-F1763)+M1764+L1764) -> 625.8
A1765: 45908.208 | B1765: =MOD(A1765,1) -> 0.20833333 | C1765: 0 | D1765: 489.544 | E1765: =D1765-0.155 -> 489.389 | F1765: =_xlfn.XLOOKUP(D1765,'Rating Curve'!$A$2:$A$500,'Rating Curve'!$D$2:$D$500,, -1) -> 1625463.8 | G1765: 489.545 | H1765: =IF(D1765 - G1765 < 0, 0, D1765 - G1765) -> 0 | I1765: 1.82 | J1765: =1.82*30*(H1765^1.5) -> 0 | L1765: =(J1765*86400)/24 -> 0 | M1765: 625.8 | O1765: =IF((F1765-F1764)+M1765+L1765 < 0, 0, (F1765-F1764)+M1765+L1765) -> 625.8
A1766: 45908.25 | B1766: =MOD(A1766,1) -> 0.25 | C1766: 0 | D1766: 489.544 | E1766: =D1766-0.155 -> 489.389 | F1766: =_xlfn.XLOOKUP(D1766,'Rating Curve'!$A$2:$A$500,'Rating Curve'!$D$2:$D$500,, -1) -> 1625463.8 | G1766: 489.545 | H1766: =IF(D1766 - G1766 < 0, 0, D1766 - G1766) -> 0 | I1766: 1.82 | J1766: =1.82*30*(H1766^1.5) -> 0 | L1766: =(J1766*86400)/24 -> 0 | M1766: 625.8 | O1766: =IF((F1766-F1765)+M1766+L1766 < 0, 0, (F1766-F1765)+M1766+L1766) -> 625.8
A1767: 45908.292 | B1767: =MOD(A1767,1) -> 0.29166667 | C1767: 0 | D1767: 489.544 | E1767: =D1767-0.155 -> 489.389 | F1767: =_xlfn.XLOOKUP(D1767,'Rating Curve'!$A$2:$A$500,'Rating Curve'!$D$2:$D$500,, -1) -> 1625463.8 | G1767: 489.545 | H1767: =IF(D1767 - G1767 < 0, 0, D1767 - G1767) -> 0 | I1767: 1.82 | J1767: =1.82*30*(H1767^1.5) -> 0 | L1767: =(J1767*86400)/24 -> 0 | M1767: 625.8 | O1767: =IF((F1767-F1766)+M1767+L1767 < 0, 0, (F1767-F1766)+M1767+L1767) -> 625.8
A1768: 45908.333 | B1768: =MOD(A1768,1) -> 0.33333333 | C1768: 0 | D1768: 489.543 | E1768: =D1768-0.155 -> 489.388 | F1768: =_xlfn.XLOOKUP(D1768,'Rating Curve'!$A$2:$A$500,'Rating Curve'!$D$2:$D$500,, -1) -> 1625463.8 | G1768: 489.545 | H1768: =IF(D1768 - G1768 < 0, 0, D1768 - G1768) -> 0 | I1768: 1.82 | J1768: =1.82*30*(H1768^1.5) -> 0 | L1768: =(J1768*86400)/24 -> 0 | M1768: 625.8 | O1768: =IF((F1768-F1767)+M1768+L1768 < 0, 0, (F1768-F1767)+M1768+L1768) -> 625.8
A1769: 45908.375 | B1769: =MOD(A1769,1) -> 0.375 | C1769: 0 | D1769: 489.543 | E1769: =D1769-0.155 -> 489.388 | F1769: =_xlfn.XLOOKUP(D1769,'Rating Curve'!$A$2:$A$500,'Rating Curve'!$D$2:$D$500,, -1) -> 1625463.8 | G1769: 489.545 | H1769: =IF(D1769 - G1769 < 0, 0, D1769 - G1769) -> 0 | I1769: 1.82 | J1769: =1.82*30*(H1769^1.5) -> 0 | L1769: =(J1769*86400)/24 -> 0 | M1769: 625.8 | O1769: =IF((F1769-F1768)+M1769+L1769 < 0, 0, (F1769-F1768)+M1769+L1769) -> 625.8
A1770: 45908.417 | B1770: =MOD(A1770,1) -> 0.41666667 | C1770: 0 | D1770: 489.543 | E1770: =D1770-0.155 -> 489.388 | F1770: =_xlfn.XLOOKUP(D1770,'Rating Curve'!$A$2:$A$500,'Rating Curve'!$D$2:$D$500,, -1) -> 1625463.8 | G1770: 489.545 | H1770: =IF(D1770 - G1770 < 0, 0, D1770 - G1770) -> 0 | I1770: 1.82 | J1770: =1.82*30*(H1770^1.5) -> 0 | L1770: =(J1770*86400)/24 -> 0 | M1770: 625.8 | O1770: =IF((F1770-F1769)+M1770+L1770 < 0, 0, (F1770-F1769)+M1770+L1770) -> 625.8
... A1783: 45908.958 | B1783: =MOD(A1783,1) -> 0.95833333 | C1783: 0 | D1783: 489.524 | E1783: =D1783-0.155 -> 489.369 | F1783: =_xlfn.XLOOKUP(D1783,'Rating Curve'!$A$2:$A$500,'Rating Curve'!$D$2:$D$500,, -1) -> 1619451.3 | G1783: 489.545 | H1783: =IF(D1783 - G1783 < 0, 0, D1783 - G1783) -> 0 | I1783: 1.82 | J1783: =1.82*30*(H1783^1.5) -> 0 | L1783: =(J1783*86400)/24 -> 0 | M1783: 625.8 | O1783: =IF((F1783-F1782)+M1783+L1783 < 0, 0, (F1783-F1782)+M1783+L1783) -> 625.8
A1784: =A1783 + TIME(1,0,0) -> 45909 | B1784: =MOD(A1784,1) -> 0 | C1784: 0 | D1784: 489.518 | E1784: =D1784-0.155 -> 489.363 | F1784: =_xlfn.XLOOKUP(D1784,'Rating Curve'!$A$2:$A$500,'Rating Curve'!$D$2:$D$500,, -1) -> 1616447.3 | G1784: 489.545 | H1784: =IF(D1784 - G1784 < 0, 0, D1784 - G1784) -> 0 | I1784: 1.82 | J1784: =1.82*30*(H1784^1.5) -> 0 | L1784: =(J1784*86400)/24 -> 0 | M1784: 625.8 | O1784: =IF((F1784-F1783)+M1784+L1784 < 0, 0, (F1784-F1783)+M1784+L1784) -> 0
A1785: =A1784 + TIME(1,0,0) -> 45909.042 | B1785: =MOD(A1785,1) -> 0.041666667 | C1785: 0 | D1785: 489.518 | E1785: =D1785-0.155 -> 489.363 | F1785: =_xlfn.XLOOKUP(D1785,'Rating Curve'!$A$2:$A$500,'Rating Curve'!$D$2:$D$500,, -1) -> 1616447.3 | G1785: 489.545 | H1785: =IF(D1785 - G1785 < 0, 0, D1785 - G1785) -> 0 | I1785: 1.82 | J1785: =1.82*30*(H1785^1.5) -> 0 | L1785: =(J1785*86400)/24 -> 0 | M1785: 625.8 | O1785: =IF((F1785-F1784)+M1785+L1785 < 0, 0, (F1785-F1784)+M1785+L1785) -> 625.8
A1786: =A1785 + TIME(1,0,0) -> 45909.083 | B1786: =MOD(A1786,1) -> 0.083333333 | C1786: 0 | D1786: 489.518 | E1786: =D1786-0.155 -> 489.363 | F1786: =_xlfn.XLOOKUP(D1786,'Rating Curve'!$A$2:$A$500,'Rating Curve'!$D$2:$D$500,, -1) -> 1616447.3 | G1786: 489.545 | H1786: =IF(D1786 - G1786 < 0, 0, D1786 - G1786) -> 0 | I1786: 1.82 | J1786: =1.82*30*(H1786^1.5) -> 0 | L1786: =(J1786*86400)/24 -> 0 | M1786: 625.8 | O1786: =IF((F1786-F1785)+M1786+L1786 < 0, 0, (F1786-F1785)+M1786+L1786) -> 625.8
A1787: =A1786 + TIME(1,0,0) -> 45909.125 | B1787: =MOD(A1787,1) -> 0.125 | C1787: 0 | D1787: 489.518 | E1787: =D1787-0.155 -> 489.363 | F1787: =_xlfn.XLOOKUP(D1787,'Rating Curve'!$A$2:$A$500,'Rating Curve'!$D$2:$D$500,, -1) -> 1616447.3 | G1787: 489.545 | H1787: =IF(D1787 - G1787 < 0, 0, D1787 - G1787) -> 0 | I1787: 1.82 | J1787: =1.82*30*(H1787^1.5) -> 0 | L1787: =(J1787*86400)/24 -> 0 | M1787: 625.8 | O1787: =IF((F1787-F1786)+M1787+L1787 < 0, 0, (F1787-F1786)+M1787+L1787) -> 625.8
A1788: =A1787 + TIME(1,0,0) -> 45909.167 | B1788: =MOD(A1788,1) -> 0.16666667 | C1788: 0 | D1788: 489.518 | E1788: =D1788-0.155 -> 489.363 | F1788: =_xlfn.XLOOKUP(D1788,'Rating Curve'!$A$2:$A$500,'Rating Curve'!$D$2:$D$500,, -1) -> 1616447.3 | G1788: 489.545 | H1788: =IF(D1788 - G1788 < 0, 0, D1788 - G1788) -> 0 | I1788: 1.82 | J1788: =1.82*30*(H1788^1.5) -> 0 | L1788: =(J1788*86400)/24 -> 0 | M1788: 625.8 | O1788: =IF((F1788-F1787)+M1788+L1788 < 0, 0, (F1788-F1787)+M1788+L1788) -> 625.8
A1789: =A1788 + TIME(1,0,0) -> 45909.208 | B1789: =MOD(A1789,1) -> 0.20833333 | C1789: 0 | D1789: 489.511 | E1789: =D1789-0.155 -> 489.356 | F1789: =_xlfn.XLOOKUP(D1789,'Rating Curve'!$A$2:$A$500,'Rating Curve'!$D$2:$D$500,, -1) -> 1616447.3 | G1789: 489.545 | H1789: =IF(D1789 - G1789 < 0, 0, D1789 - G1789) -> 0 | I1789: 1.82 | J1789: =1.82*30*(H1789^1.5) -> 0 | L1789: =(J1789*86400)/24 -> 0 | M1789: 625.8 | O1789: =IF((F1789-F1788)+M1789+L1789 < 0, 0, (F1789-F1788)+M1789+L1789) -> 625.8
A1790: =A1789 + TIME(1,0,0) -> 45909.25 | B1790: =MOD(A1790,1) -> 0.25 | C1790: 0 | D1790: 489.518 | E1790: =D1790-0.155 -> 489.363 | F1790: =_xlfn.XLOOKUP(D1790,'Rating Curve'!$A$2:$A$500,'Rating Curve'!$D$2:$D$500,, -1) -> 1616447.3 | G1790: 489.545 | H1790: =IF(D1790 - G1790 < 0, 0, D1790 - G1790) -> 0 | I1790: 1.82 | J1790: =1.82*30*(H1790^1.5) -> 0 | L1790: =(J1790*86400)/24 -> 0 | M1790: 625.8 | O1790: =IF((F1790-F1789)+M1790+L1790 < 0, 0, (F1790-F1789)+M1790+L1790) -> 625.8
A1791: =A1790 + TIME(1,0,0) -> 45909.292 | B1791: =MOD(A1791,1) -> 0.29166667 | C1791: 0 | D1791: 489.511 | E1791: =D1791-0.155 -> 489.356 | F1791: =_xlfn.XLOOKUP(D1791,'Rating Curve'!$A$2:$A$500,'Rating Curve'!$D$2:$D$500,, -1) -> 1616447.3 | G1791: 489.545 | H1791: =IF(D1791 - G1791 < 0, 0, D1791 - G1791) -> 0 | I1791: 1.82 | J1791: =1.82*30*(H1791^1.5) -> 0 | L1791: =(J1791*86400)/24 -> 0 | M1791: 625.8 | O1791: =IF((F1791-F1790)+M1791+L1791 < 0, 0, (F1791-F1790)+M1791+L1791) -> 625.8
A1792: =A1791 + TIME(1,0,0) -> 45909.333 | B1792: =MOD(A1792,1) -> 0.33333333 | C1792: 0 | D1792: 489.517 | E1792: =D1792-0.155 -> 489.362 | F1792: =_xlfn.XLOOKUP(D1792,'Rating Curve'!$A$2:$A$500,'Rating Curve'!$D$2:$D$500,, -1) -> 1616447.3 | G1792: 489.545 | H1792: =IF(D1792 - G1792 < 0, 0, D1792 - G1792) -> 0 | I1792: 1.82 | J1792: =1.82*30*(H1792^1.5) -> 0 | L1792: =(J1792*86400)/24 -> 0 | M1792: 625.8 | O1792: =IF((F1792-F1791)+M1792+L1792 < 0, 0, (F1792-F1791)+M1792+L1792) -> 625.8
A1793: =A1792 + TIME(1,0,0) -> 45909.375 | B1793: =MOD(A1793,1) -> 0.375 | C1793: 0 | D1793: 489.517 | E1793: =D1793-0.155 -> 489.362 | F1793: =_xlfn.XLOOKUP(D1793,'Rating Curve'!$A$2:$A$500,'Rating Curve'!$D$2:$D$500,, -1) -> 1616447.3 | G1793: 489.545 | H1793: =IF(D1793 - G1793 < 0, 0, D1793 - G1793) -> 0 | I1793: 1.82 | J1793: =1.82*30*(H1793^1.5) -> 0 | L1793: =(J1793*86400)/24 -> 0 | M1793: 625.8 | O1793: =IF((F1793-F1792)+M1793+L1793 < 0, 0, (F1793-F1792)+M1793+L1793) -> 625.8
A1794: =A1793 + TIME(1,0,0) -> 45909.417 | B1794: =MOD(A1794,1) -> 0.41666667 | C1794: 0 | D1794: 489.511 | E1794: =D1794-0.155 -> 489.356 | F1794: =_xlfn.XLOOKUP(D1794,'Rating Curve'!$A$2:$A$500,'Rating Curve'!$D$2:$D$500,, -1) -> 1616447.3 | G1794: 489.545 | H1794: =IF(D1794 - G1794 < 0, 0, D1794 - G1794) -> 0 | I1794: 1.82 | J1794: =1.82*30*(H1794^1.5) -> 0 | L1794: =(J1794*86400)/24 -> 0 | M1794: 625.8 | O1794: =IF((F1794-F1793)+M1794+L1794 < 0, 0, (F1794-F1793)+M1794+L1794) -> 625.8
A1795: =A1794 + TIME(1,0,0) -> 45909.458 | B1795: =MOD(A1795,1) -> 0.45833333 | C1795: 0 | D1795: 489.511 | E1795: =D1795-0.155 -> 489.356 | F1795: =_xlfn.XLOOKUP(D1795,'Rating Curve'!$A$2:$A$500,'Rating Curve'!$D$2:$D$500,, -1) -> 1616447.3 | G1795: 489.545 | H1795: =IF(D1795 - G1795 < 0, 0, D1795 - G1795) -> 0 | I1795: 1.82 | J1795: =1.82*30*(H1795^1.5) -> 0 | L1795: =(J1795*86400)/24 -> 0 | M1795: 625.8 | O1795: =IF((F1795-F1794)+M1795+L1795 < 0, 0, (F1795-F1794)+M1795+L1795) -> 625.8
...

Sheet Sheet1
A1: Date | B1: Q_in_t (m³/day) | C1: Water_Level_t (m) | D1: Storage_S_t (m³) | E1: DeltaS_t (m³/day) | F1: %Full_t | G1: Rainfall (mm) | H1: API_t (mm) | I1: DOY | J1: DOY_sin | K1: DOY_cos | L1: Q_lag1 (m³/day) | M1: Q_lag2 (m³/day) | N1: Q_lag3 (m³/day) | O1: Q_lag7 (m³/day) | P1: Q_lag14 (m³/day) | Q1: Rain_obs_sum3 (mm) | R1: Rain_obs_sum7 (mm) | S1: Rain_obs_sum14 (mm) | T1: Q_mean_3d | U1: Outflow_lag1 (m³/day) | V1: Spill_lag1 (m³/day) | W1: Outflow_lag2 (m³/day) | X1: Spill_lag2 (m³/day) | Y1: Outflow_lag3 (m³/day) | Z1: Spill_lag3 (m³/day) | AA1: Rain_fcst_d1 (mm) | AB1: Rain_fcst_d2 (mm) | AC1: Rain_fcst_d3 (mm) | AD1: Rain_fcst_sum1_3 (mm) | AE1: Rain_fcst_max1_3 (mm) | AF1: y1=Q_in_t+1 (m³/day) | AG1: y2=Q_in_t+2 (m³/day) | AH1: y3=Q_in_t+3 (m³/day)
A2: 45839 | B2: 16137.621 | C2: 489.518 | D2: 1616447.3 | F2: 0.99445299 | G2: 0 | H2: 0 | I2: 182 | J2: 0.0086069969 | K2: -0.99996296 | AA2: 13.673 | AB2: 6.699 | AC2: 4.328 | AD2: 24.7 | AE2: 13.673 | AF2: 18000.43 | AG2: 16551.136 | AH2: 21950.322
A3: 45840 | B3: 18000.43 | C3: 489.524 | D3: 1619451.3 | E3: 3004.017 | F3: 0.99630109 | G3: 3.8 | H3: 3.8 | I3: 183 | J3: -0.0086069969 | K3: -0.99996296 | L3: 16137.621 | U3: 15019.2 | V3: 0 | AA3: 6.699 | AB3: 4.328 | AC3: 10.32 | AD3: 21.347 | AE3: 10.32 | AF3: 16551.136 | AG3: 21950.322 | AH3: 22689.828
A4: 45841 | B4: 16551.136 | C4: 489.524 | D4: 1619451.3 | E4: 0 | F4: 0.99630109 | G4: 0 | H4: 3.61 | I4: 184 | J4: -0.02581844 | K4: -0.99966665 | L4: 18000.43 | M4: 16137.621 | U4: 15019.2 | V4: 0 | W4: 15019.2 | X4: 0 | AA4: 4.328 | AB4: 10.32 | AC4: 4.29 | AD4: 18.938 | AE4: 10.32 | AF4: 21950.322 | AG4: 22689.828 | AH4: 41715.189
A5: 45842 | B5: 21950.322 | C5: 489.557 | D5: 1628472.3 | E5: 9020.9887 | F5: 1.0018509 | G5: 30.2 | H5: 33.6295 | I5: 185 | J5: -0.043022233 | K5: -0.99907412 | L5: 16551.136 | M5: 18000.43 | N5: 16137.621 | Q5: 34 | T5: 18833.963 | U5: 15019.2 | V5: 412.94112 | W5: 15019.2 | X5: 0 | Y5: 15019.2 | Z5: 0 | AA5: 10.32 | AB5: 4.29 | AC5: 1.138 | AD5: 15.748 | AE5: 10.32 | AF5: 22689.828 | AG5: 41715.189 | AH5: 41682.058
A6: 45843 | B6: 22689.828 | C6: 489.557 | D6: 1628472.3 | E6: 0 | F6: 1.0018509 | G6: 0.4 | H6: 32.348025 | I6: 186 | J6: -0.060213277 | K6: -0.99818553 | L6: 21950.322 | M6: 16551.136 | N6: 18000.43 | Q6: 30.6 | T6: 20397.095 | U6: 15019.2 | V6: 5877.4746 | W6: 15019.2 | X6: 412.94112 | Y6: 15019.2 | Z6: 0 | AA6: 4.29 | AB6: 1.138 | AC6: 13.004 | AD6: 18.432 | AE6: 13.004 | AF6: 41715.189 | AG6: 41682.058 | AH6: 38705.212
A7: 45844 | B7: 41715.189 | C7: 489.577 | D7: 1634494 | E7: 6021.7108 | F7: 1.0055555 | G7: 17.2 | H7: 47.930624 | I7: 187 | J7: -0.077386479 | K7: -0.99700117 | L7: 22689.828 | M7: 21950.322 | N7: 16551.136 | Q7: 47.8 | T7: 28785.113 | U7: 15019.2 | V7: 6670.2723 | W7: 15019.2 | X7: 5877.4746 | Y7: 15019.2 | Z7: 412.94112 | AA7: 1.138 | AB7: 13.004 | AC7: 9.394 | AD7: 23.536 | AE7: 13.004 | AF7: 41682.058 | AG7: 38705.212 | AH7: 33915.235
A8: 45845 | B8: 41682.058 | C8: 489.577 | D8: 1634494 | E8: 0 | F8: 1.0055555 | G8: 0 | H8: 45.534093 | I8: 188 | J8: -0.09453675 | K8: -0.99552137 | L8: 41715.189 | M8: 22689.828 | N8: 21950.322 | Q8: 17.6 | T8: 35362.358 | U8: 15019.2 | V8: 24733.704 | W8: 15019.2 | X8: 6670.2723 | Y8: 15019.2 | Z8: 5877.4746 | AA8: 13.004 | AB8: 9.394 | AC8: 1.67 | AD8: 24.068 | AE8: 13.004 | AF8: 38705.212 | AG8: 33915.235 | AH8: 16680.986
A9: 45846 | B9: 38705.212 | C9: 489.577 | D9: 1634494 | E9: 0 | F9: 1.0055555 | G9: 0 | H9: 43.257388 | I9: 189 | J9: -0.11165901 | K9: -0.99374658 | L9: 41682.058 | M9: 41715.189 | N9: 22689.828 | O9: 16137.621 | Q9: 17.2 | R9: 51.6 | T9: 40700.82 | U9: 15019.2 | V9: 25540.965 | W9: 15019.2 | X9: 24733.704 | Y9: 15019.2 | Z9: 6670.2723 | AA9: 9.394 | AB9: 1.67 | AC9: 10.659 | AD9: 21.723 | AE9: 10.659 | AF9: 33915.235 | AG9: 16680.986 | AH9: 9699.6258
A10: 45847 | B10: 33915.235 | C10: 489.57 | D10: 1634494 | E10: 0 | F10: 1.0055555 | G10: 0 | H10: 41.094519 | I10: 190 | J10: -0.12874818 | K10: -0.99167732 | L10: 38705.212 | M10: 41682.058 | N10: 41715.189 | O10: 18000.43 | Q10: 0 | R10: 47.8 | T10: 38100.835 | U10: 15019.2 | V10: 22564.119 | W10: 15019.2 | X10: 25540.965 | Y10: 15019.2 | Z10: 24733.704 | AA10: 1.67 | AB10: 10.659 | AC10: 20.48 | AD10: 32.809 | AE10: 20.48 | AF10: 16680.986 | AG10: 9699.6258 | AH10: 20534.223
A11: 45848 | B11: 16680.986 | C11: 489.564 | D11: 1631482.4 | E11: -3011.6213 | F11: 1.0037027 | G11: 8.6 | H11: 47.639793 | I11: 191 | J11: -0.1457992 | K11: -0.9893142 | L11: 33915.235 | M11: 38705.212 | N11: 41682.058 | O11: 16551.136 | Q11: 8.6 | R11: 56.4 | T11: 29767.144 | U11: 15019.2 | V11: 17774.142 | W11: 15019.2 | X11: 22564.119 | Y11: 15019.2 | Z11: 25540.965 | AA11: 10.659 | AB11: 20.48 | AC11: 22.463 | AD11: 53.602 | AE11: 22.463 | AF11: 9699.6258 | AG11: 20534.223 | AH11: 62384.338
A12: 45849 | B12: 9699.6258 | C12: 489.544 | D12: 1625463.8 | E12: -6018.6362 | F12: 1 | G12: 1.4 | H12: 46.657803 | I12: 192 | J12: -0.16280701 | K12: -0.98665793 | L12: 16680.986 | M12: 33915.235 | N12: 38705.212 | O12: 21950.322 | Q12: 10 | R12: 27.6 | T12: 20098.615 | U12: 15019.2 | V12: 6141.422 | W12: 15019.2 | X12: 17774.142 | Y12: 15019.2 | Z12: 22564.119 | AA12: 20.48 | AB12: 22.463 | AC12: 18.722 | AD12: 61.665 | AE12: 22.463 | AF12: 20534.223 | AG12: 62384.338 | AH12: 48379.885
A13: 45850 | B13: 20534.223 | C13: 489.531 | D13: 1622456.8 | E13: -3006.9861 | F13: 0.99815007 | G13: 5.2 | H13: 49.524913 | I13: 193 | J13: -0.17976659 | K13: -0.98370929 | L13: 9699.6258 | M13: 16680.986 | N13: 33915.235 | O13: 22689.828 | Q13: 15.2 | R13: 32.4 | T13: 15638.278 | U13: 15019.2 | V13: 0 | W13: 15019.2 | X13: 6141.422 | Y13: 15019.2 | Z13: 17774.142 | AA13: 22.463 | AB13: 18.722 | AC13: 18.886 | AD13: 60.071 | AE13: 22.463 | AF13: 62384.338 | AG13: 48379.885 | AH13: 38218.92
A14: 45851 | B14: 62384.338 | C14: 489.589 | D14: 1637507.2 | E14: 15050.447 | F14: 1.0074092 | G14: 31.6 | H14: 78.648667 | I14: 194 | J14: -0.19667289 | K14: -0.98046916 | L14: 20534.223 | M14: 9699.6258 | N14: 16680.986 | O14: 41715.189 | Q14: 38.2 | R14: 46.8 | T14: 30872.729 | U14: 15019.2 | V14: 8965.6721 | W14: 15019.2 | X14: 0 | Y14: 15019.2 | Z14: 6141.422 | AA14: 18.722 | AB14: 18.886 | AC14: 8.722 | AD14: 46.33 | AE14: 18.886 | AF14: 48379.885 | AG14: 38218.92 | AH14: 783908.45
A15: 45852 | B15: 48379.885 | C15: 489.583 | D15: 1637507.2 | E15: 0 | F15: 1.0074092 | G15: 0 | H15: 74.716234 | I15: 195 | J15: -0.21352092 | K15: -0.97693849 | L15: 62384.338 | M15: 20534.223 | N15: 9699.6258 | O15: 41682.058 | Q15: 36.8 | R15: 46.8 | T15: 43766.149 | U15: 15019.2 | V15: 40716.29 | W15: 15019.2 | X15: 8965.6721 | Y15: 15019.2 | Z15: 0 | AA15: 18.886 | AB15: 8.722 | AC15: 11.64 | AD15: 39.248 | AE15: 18.886 | AF15: 38218.92 | AG15: 783908.45 | AH15: 421045.59
A16: 45853 | B16: 38218.92 | C16: 489.57 | D16: 1634494 | E16: -3013.2032 | F16: 1.0055555 | G16: 0 | H16: 70.980422 | I16: 196 | J16: -0.23030567 | K16: -0.97311834 | L16: 48379.885 | M16: 62384.338 | N16: 20534.223 | O16: 38705.212 | P16: 16137.621 | Q16: 31.6 | R16: 46.8 | S16: 98.4 | T16: 49661.047 | U16: 15019.2 | V16: 32238.208 | W16: 15019.2 | X16: 40716.29 | Y16: 15019.2 | Z16: 8965.6721 | AA16: 8.722 | AB16: 11.64 | AC16: 14.796 | AD16: 35.158 | AE16: 14.796 | AF16: 783908.45 | AG16: 421045.59 | AH16: 247151.6
A17: 45854 | B17: 783908.45 | C17: 489.853 | D17: 1719668.7 | E17: 85174.686 | F17: 1.0579557 | G17: 78.8 | H17: 146.2314 | I17: 197 | J17: -0.24702218 | K17: -0.96900983 | L17: 38218.92 | M17: 48379.885 | N17: 62384.338 | O17: 33915.235 | P17: 18000.43 | Q17: 78.8 | R17: 125.6 | S17: 173.4 | T17: 290169.08 | U17: 15019.2 | V17: 25091.03 | W17: 15019.2 | X17: 32238.208 | Y17: 15019.2 | Z17: 40716.29 | AA17: 11.64 | AB17: 14.796 | AC17: 4.428 | AD17: 30.864 | AE17: 14.796 | AF17: 421045.59 | AG17: 247151.6 | AH17: 142706.72
A18: 45855 | B18: 421045.59 | C18: 489.763 | D18: 1692113.7 | E18: -27555.041 | F18: 1.0410036 | G18: 4.2 | H18: 143.11983 | I18: 198 | J18: -0.26366549 | K18: -0.96461418 | L18: 783908.45 | M18: 38218.92 | N18: 48379.885 | O18: 16680.986 | P18: 16551.136 | Q18: 83 | R18: 121.2 | S18: 177.6 | T18: 414390.99 | U18: 15019.2 | V18: 706792.16 | W18: 15019.2 | X18: 25091.03 | Y18: 15019.2 | Z18: 32238.208 | AA18: 14.796 | AB18: 4.428 | AC18: 6.208 | AD18: 25.432 | AE18: 14.796 | AF18: 247151.6 | AG18: 142706.72 | AH18: 99633.962
A19: 45856 | B19: 247151.6 | C19: 489.698 | D19: 1670813.5 | E19: -21300.179 | F19: 1.0278996 | G19: 4.2 | H19: 140.16384 | I19: 199 | J19: -0.28023068 | K19: -0.95993269 | L19: 421045.59 | M19: 783908.45 | N19: 38218.92 | O19: 9699.6258 | P19: 21950.322 | Q19: 87.2 | R19: 124 | S19: 151.6 | T19: 484035.22 | U19: 15019.2 | V19: 433726.35 | W19: 15019.2 | X19: 706792.16 | Y19: 15019.2 | Z19: 25091.03 | AA19: 4.428 | AB19: 6.208 | AC19: 33.034 | AD19: 43.67 | AE19: 33.034 | AF19: 142706.72 | AG19: 99633.962 | AH19: 81725.689
A20: 45857 | B20: 142706.72 | C20: 489.648 | D20: 1655645.2 | E20: -15168.321 | F20: 1.0185679 | G20: 0 | H20: 133.15565 | I20: 200 | J20: -0.29671282 | K20: -0.95496675 | L20: 247151.6 | M20: 421045.59 | N20: 783908.45 | O20: 20534.223 | P20: 22689.828 | Q20: 8.4 | R20: 118.8 | S20: 151.2 | T20: 270301.31 | U20: 15019.2 | V20: 253577.02 | W20: 15019.2 | X20: 433726.35 | Y20: 15019.2 | Z20: 706792.16 | AA20: 6.208 | AB20: 33.034 | AC20: 3.545 | AD20: 42.787 | AE20: 33.034 | AF20: 99633.962 | AG20: 81725.689 | AH20: 54196.435
A21: 45858 | B21: 99633.962 | C21: 489.608 | D21: 1643538.2 | E21: -12106.945 | F21: 1.0111196 | G21: 0 | H21: 126.49787 | I21: 201 | J21: -0.31310704 | K21: -0.94971784 | L21: 142706.72 | M21: 247151.6 | N21: 421045.59 | O21: 62384.338 | P21: 41715.189 | Q21: 4.2 | R21: 87.2 | S21: 134 | T21: 163164.09 | U21: 15019.2 | V21: 141727.38 | W21: 15019.2 | X21: 253577.02 | Y21: 15019.2 | Z21: 433726.35 | AA21: 33.034 | AB21: 3.545 | AC21: 12.694 | AD21: 49.273 | AE21: 33.034 | AF21: 81725.689 | AG21: 54196.435 | AH21: 1408228.3
A22: 45859 | B22: 81725.689 | C22: 489.608 | D22: 1643538.2 | E22: 0 | F22: 1.0111196 | G22: 19.8 | H22: 139.97297 | I22: 202 | J22: -0.32940848 | K22: -0.94418751 | L22: 99633.962 | M22: 142706.72 | N22: 247151.6 | O22: 48379.885 | P22: 41682.058 | Q22: 19.8 | R22: 107 | S22: 153.8 | T22: 108022.12 | U22: 15019.2 | V22: 95597.933 | W22: 15019.2 | X22: 141727.38 | Y22: 15019.2 | Z22: 253577.02 | AA22: 3.545 | AB22: 12.694 | AC22: 6.008 | AD22: 22.247 | AE22: 12.694 | AF22: 54196.435 | AG22: 1408228.3 | AH22: 1123235
A23: 45860 | B23: 54196.435 | C23: 489.589 | D23: 1637507.2 | E23: -6030.9967 | F23: 1.0074092 | G23: 0 | H23: 132.97432 | I23: 203 | J23: -0.34561231 | K23: -0.93837739 | L23: 81725.689 | M23: 99633.962 | N23: 142706.72 | O23: 38218.92 | P23: 38705.212 | Q23: 19.8 | R23: 107 | S23: 153.8 | T23: 78518.695 | U23: 15019.2 | V23: 71557.166 | W23: 15019.2 | X23: 95597.933 | Y23: 15019.2 | Z23: 141727.38 | AA23: 12.694 | AB23: 6.008 | AC23: 4.704 | AD23: 23.406 | AE23: 12.694 | AF23: 1408228.3 | AG23: 1123235 | AH23: 618651.26
A24: 45861 | B24: 1408228.3 | C24: 489.801 | D24: 1704320.3 | E24: 66813.048 | F24: 1.0485132 | G24: 58.6 | H24: 184.92561 | I24: 204 | J24: -0.36171373 | K24: -0.93228921 | L24: 54196.435 | M24: 81725.689 | N24: 99633.962 | O24: 783908.45 | P24: 33915.235 | Q24: 78.4 | R24: 86.8 | S24: 212.4 | T24: 514716.81 | U24: 15019.2 | V24: 44085.754 | W24: 15019.2 | X24: 71557.166 | Y24: 15019.2 | Z24: 95597.933 | AA24: 6.008 | AB24: 4.704 | AC24: 4.006 | AD24: 14.718 | AE24: 6.008 | AF24: 1123235 | AG24: 618651.26 | AH24: 482554.31
A25: 45862 | B25: 1123235 | C25: 489.943 | D25: 1747400.3 | E25: 43080.027 | F25: 1.0750165 | G25: 39.8 | H25: 215.47933 | I25: 205 | J25: -0.37770797 | K25: -0.92592478 | L25: 1408228.3 | M25: 54196.435 | N25: 81725.689 | O25: 421045.59 | P25: 16680.986 | Q25: 98.4 | R25: 122.4 | S25: 243.6 | T25: 861886.6 | U25: 15019.2 | V25: 1343213.8 | W25: 15019.2 | X25: 44085.754 | Y25: 15019.2 | Z25: 71557.166 | AA25: 4.704 | AB25: 4.006 | AC25: 21.497 | AD25: 30.207 | AE25: 21.497 | AF25: 618651.26 | AG25: 482554.31 | AH25: 569451.16
A26: 45863 | B26: 618651.26 | C26: 489.82098 | D26: 1710454.4 | E26: -36945.858 | F26: 1.052287 | G26: 8.8 | H26: 213.50536 | I26: 206 | J26: -0.39359028 | K26: -0.91928597 | L26: 1123235 | M26: 1408228.3 | N26: 54196.435 | O26: 247151.6 | P26: 9699.6258 | Q26: 107.2 | R26: 127 | S26: 251 | T26: 1050038.2 | U26: 15019.2 | V26: 1076278.5 | W26: 15019.2 | X26: 1343213.8 | Y26: 15019.2 | Z26: 44085.754 | AA26: 4.006 | AB26: 21.497 | AC26: 5.961 | AD26: 31.464 | AE26: 21.497 | AF26: 482554.31 | AG26: 569451.16 | AH26: 1013858.9
A27: 45864 | B27: 482554.31 | C27: 489.769 | D27: 1692113.7 | E27: -18340.775 | F27: 1.0410036 | G27: 6 | H27: 208.83009 | I27: 207 | J27: -0.40935596 | K27: -0.91237476 | L27: 618651.26 | M27: 1123235 | N27: 1408228.3 | O27: 142706.72 | P27: 20534.223 | Q27: 54.6 | R27: 133 | S27: 251.8 | T27: 741480.2 | U27: 15019.2 | V27: 642135.52 | W27: 15019.2 | X27: 1076278.5 | Y27: 15019.2 | Z27: 1343213.8 | AA27: 21.497 | AB27: 5.961 | AC27: 12.932 | AD27: 40.39 | AE27: 21.497 | AF27: 569451.16 | AG27: 1013858.9 | AH27: 693172.31
... A216: 46053 | B216: 20308.696 | C216: 489.567 | D216: 1631482.4 | E216: 0 | F216: 1.0037027 | G216: 0 | H216: 3.806416 | I216: 31 | J216: 0.50867094 | K216: 0.86096102 | L216: 17667.161 | M216: 26063.734 | N216: 18494.035 | O216: 15169.122 | P216: 21070.653 | Q216: 0 | R216: 0 | S216: 0 | T216: 21346.53 | U216: 0 | V216: 19700.313 | W216: 0 | X216: 22073.133 | Y216: 0 | Z216: 20527.188 | AA216: 0 | AB216: 0 | AC216: 0 | AD216: 0 | AE216: 0 | AF216: 0 | AG216: 0 | AH216: 0

Sheet Rating Curve
A1: MSL_Height | B1: Z_Factor | C1: พื้นที่ผิวน้ำ | D1: ความจุ(ลูกบาศก์เมตร)
A2: 490.5 | B2: 1 | C2: 325588.17 | D2: 1924831.9
A3: 490.49 | B3: 1 | C3: 325329.54 | D3: 1921577.3
A4: 490.48 | B4: 1 | C4: 325070.96 | D4: 1918325.3
A5: 490.47 | B5: 1 | C5: 324812.56 | D5: 1915075.8
A6: 490.46 | B6: 1 | C6: 324554.24 | D6: 1911828.9
A7: 490.45 | B7: 1 | C7: 324296.2 | D7: 1908584.6
A8: 490.44 | B8: 1 | C8: 324038.37 | D8: 1905343
A9: 490.43 | B9: 1 | C9: 323780.31 | D9: 1902103.9
A10: 490.42 | B10: 1 | C10: 323520.96 | D10: 1898867.4
A11: 490.41 | B11: 1 | C11: 323254.77 | D11: 1895633.5
A12: 490.4 | B12: 1 | C12: 322850.9 | D12: 1892402.5
A13: 490.39 | B13: 1 | C13: 321169.49 | D13: 1889188.9
... A97: 489.55 | B97: 1 | C97: 300929.41 | D97: 1628472.3
A98: 489.54 | B98: 1 | C98: 300775.26 | D98: 1625463.8 | E98: Spill way
A99: 489.53 | B99: 1 | C99: 300621.71 | D99: 1622456.8
A100: 489.52 | B100: 1 | C100: 300468.72 | D100: 1619451.3
A101: 489.51 | B101: 1 | C101: 300316.3 | D101: 1616447.3
A102: 489.5 | B102: 1 | C102: 300164.53 | D102: 1613444.9
A103: 489.49 | B103: 1 | C103: 300013.28 | D103: 1610444
A104: 489.48 | B104: 1 | C104: 299862.59 | D104: 1607444.6
A105: 489.47 | B105: 1 | C105: 299712.5 | D105: 1604446.7
A106: 489.46 | B106: 1 | C106: 299562.94 | D106: 1601450.3
A107: 489.45 | B107: 1 | C107: 299413.77 | D107: 1598455.5
A108: 489.44 | B108: 1 | C108: 299264.87 | D108: 1595462
A109: 489.43 | B109: 1 | C109: 299115.74 | D109: 1592470.1
A110: 489.42 | B110: 1 | C110: 298964.86 | D110: 1589479.8
... A772: 482.8 | B772: 1 | C772: 33140.979 | D772: 0.40316732

Sheet Flow rate ท่อฝั่งทางเข้าอ่าง
A1: Flow rate measuring experiment
A2: อ่างเก็บน้ำแม่นาเรือ
A3: 1. ท่อน้ำออก ฝั่งทางเข้าอ่าง | B3: ท่อ HDPE 355 mm. (outer surface) 26.1 mm thickness PN125 | H3: ระยะห่างหัววัด 411.4 mm.
A4: จำนวนรอบที่เปิดวาล์ว | B4: รอบที่ 1 | E4: รอบที่ 2 | H4: รอบที่ 3 | K4: Avg
B5: V (m/s) | C5: Q (M3/h) | D5: Q (M3/min) | E5: V (m/s) | F5: Q (M3/h) | G5: Q (M3/min) | H5: V (m/s) | I5: Q (M3/h) | J5: Q (M3/min) | K5: V (m/s) | L5: Q (M3/h) | M5: Q (M3/min)
A6: 1 | B6: 0 | C6: 0 | D6: 0 | E6: 0 | F6: 0 | G6: 0 | H6: 0 | I6: 0 | J6: 0 | K6: 0 | L6: 0 | M6: 0
A7: 2 | B7: 0.05 | C7: 13.8 | D7: 0.23 | E7: 0.05 | F7: 13.8 | G7: 0.23 | H7: 0.05 | I7: 13.8 | J7: 0.23 | K7: 0.05 | L7: 13.8 | M7: 0.23
A8: 3 | B8: 0.27 | C8: 70.2 | D8: 1.17 | E8: 0.29 | F8: 76.8 | G8: 1.28 | H8: 0.29 | I8: 74.4 | J8: 1.24 | K8: 0.28333333 | L8: 73.8 | M8: 1.23
A9: 4 | B9: 0.57 | C9: 147.6 | D9: 2.46 | E9: 0.57 | F9: 148.8 | G9: 2.48 | H9: 0.56 | I9: 145.8 | J9: 2.43 | K9: 0.56666667 | L9: 147.4 | M9: 2.4566667
A10: 5 | B10: 0.77 | C10: 199.8 | D10: 3.33 | E10: 0.82 | F10: 214.2 | G10: 3.57 | H10: 0.77 | I10: 199.8 | J10: 3.33 | K10: 0.78666667 | L10: 204.6 | M10: 3.41
A11: 6 | B11: 0.89 | C11: 232.2 | D11: 3.87 | E11: 0.87 | F11: 227.4 | G11: 3.79 | H11: 0.91 | I11: 237 | J11: 3.95 | K11: 0.89 | L11: 232.2 | M11: 3.87 | N11: ระดับระบายหน้าฝน
A12: 7 | B12: 0.97 | C12: 252.6 | D12: 4.21 | E12: 0.96 | F12: 249 | G12: 4.15 | H12: 1 | I12: 261 | J12: 4.35 | K12: 0.97666667 | L12: 254.2 | M12: 4.2366667
A13: 8 | B13: 1.05 | C13: 272.4 | D13: 4.54 | E13: 1.06 | F13: 276.6 | G13: 4.61 | H13: 1.07 | I13: 278.4 | J13: 4.64 | K13: 1.06 | L13: 275.8 | M13: 4.5966667
A14: 9 | B14: 1.06 | C14: 276.6 | D14: 4.61 | E14: 1.07 | F14: 279.6 | G14: 4.66 | H14: 1.09 | I14: 284.4 | J14: 4.74 | K14: 1.0733333 | L14: 280.2 | M14: 4.67
A15: 10 | B15: 1.05 | C15: 273.6 | D15: 4.56 | E15: 1.08 | F15: 282 | G15: 4.7 | H15: 1.12 | I15: 291 | J15: 4.85 | K15: 1.0833333 | L15: 282.2 | M15: 4.7033333
A16: 11 | B16: 1.06 | C16: 275.4 | D16: 4.59 | E16: 1.08 | F16: 282 | G16: 4.7 | H16: 1.12 | I16: 291.6 | J16: 4.86 | K16: 1.0866667 | L16: 283 | M16: 4.7166667

Sheet Flow rate ท่อฝั่งสปิลเวย์
A1: Flow rate measuring experiment
A2: อ่างเก็บน้ำแม่นาเรือ
A3: 1. ท่อน้ำออก ฝั่งสปิลเวย์ ปล่อยลงคลองส่งน้ำคอนกรีต | B3: ท่อ HDPE 355 mm. (outer surface) 26.1 mm thickness PN125 | E3: ระยะห่างหัววัด 411 mm.
A4: จำนวนรอบที่เปิดวาล์ว | B4: รอบที่ 1 | E4: รอบที่ 2 | H4: รอบที่ 3 | K4: Avg
B5: V (m/s) | C5: Q (M3/h) | D5: Q (M3/min) | E5: V (m/s) | F5: Q (M3/h) | G5: Q (M3/min) | H5: V (m/s) | I5: Q (M3/h) | J5: Q (M3/min) | K5: V (m/s) | L5: Q (M3/h) | M5: Q (M3/min)
A6: 1 | B6: 0 | C6: 0 | D6: 0 | E6: 0 | F6: 0 | G6: 0 | H6: 0 | I6: 0 | J6: 0 | K6: 0 | L6: 0 | M6: 0
A7: 2 | B7: 0 | C7: 0 | D7: 0 | E7: 0 | F7: 0 | G7: 0 | H7: 0 | I7: 0 | J7: 0 | K7: 0 | L7: 0 | M7: 0
A8: 3 | B8: 0 | C8: 0 | D8: 0 | E8: 0 | F8: 0 | G8: 0 | H8: 0 | I8: 0 | J8: 0 | K8: 0 | L8: 0 | M8: 0
A9: 4 | B9: 0 | C9: 0 | D9: 0 | E9: 0 | F9: 0 | G9: 0 | H9: 0 | I9: 0 | J9: 0 | K9: 0 | L9: 0 | M9: 0
A10: 5 | B10: 0 | C10: 0 | D10: 0 | E10: 0 | F10: 0 | G10: 0 | H10: 0 | I10: 0 | J10: 0 | K10: 0 | L10: 0 | M10: 0
A11: 6 | B11: 1.5 | C11: 390 | D11: 6.5 | E11: 1.51 | F11: 391.8 | G11: 6.53 | H11: 1.54 | I11: 399 | J11: 6.65 | K11: 1.5166667 | L11: 393.6 | M11: 6.56 | N11: ระดับระบายหน้าฝน
A12: 7 | B12: 1.67 | C12: 433 | D12: 7.2166667 | E12: 1.7 | F12: 440.4 | G12: 7.34 | H12: 1.65 | I12: 427.8 | J12: 7.13 | K12: 1.6733333 | L12: 433.73333 | M12: 7.2288889
A13: 8 | B13: 1.74 | C13: 450 | D13: 7.5 | E13: 1.79 | F13: 463.8 | G13: 7.73 | H13: 1.79 | I13: 464.4 | J13: 7.74 | K13: 1.7733333 | L13: 459.4 | M13: 7.6566667
A14: 9 | B14: 1.75 | C14: 453 | D14: 7.55 | E14: 1.84 | F14: 477 | G14: 7.95 | H14: 1.85 | I14: 481.2 | J14: 8.02 | K14: 1.8133333 | L14: 470.4 | M14: 7.84
A15: 10 | B15: 1.76 | C15: 453 | D15: 7.64 | E15: 1.89 | F15: 490.2 | G15: 8.17 | H15: 1.89 | I15: 490.2 | J15: 8.17 | K15: 1.8466667 | L15: 477.8 | M15: 7.9933333
A16: 11 | B16: 1.81 | C16: 470 | D16: 7.8333333 | E16: 1.91 | F16: 496.2 | G16: 8.27 | H16: 1.93 | I16: 499.8 | J16: 8.33 | K16: 1.8833333 | L16: 488.66667 | M16: 8.1444444
A17: 12 | B17: 1.88 | C17: 487 | D17: 8.1166667 | E17: 1.95 | F17: 506.4 | G17: 8.44 | H17: 1.96 | I17: 508.2 | J17: 8.47 | K17: 1.93 | L17: 500.53333 | M17: 8.3422222
